Workbook

Sheet Plan - Semanal
B2: Tabacalera Espert SA
B4: Plan de Produccion | D4: Versión: | E4: 0
D5: DESDE | E5: HASTA
B6: Semana | C6: =_xlfn.ISOWEEKNUM(D6) -> 7 | D6: 46062 | E6: =D6+6 -> 46068 | M6: Semana 2 | N6: Semana 3 | O6: Semana 4
C8: =D6 -> 46062 | D8: =C8+1 -> 46063 | E8: =D8+1 -> 46064 | F8: =E8+1 -> 46065 | G8: =F8+1 -> 46066 | H8: =G8+1 -> 46067 | I8: =H8+1 -> 46068 | J8: =I8+1 -> 46069 | K8: T Semanal | M8: =C6+1 -> 8 | N8: =+M8+1 -> 9 | O8: =+N8+1 -> 10 | P8: T Mes
B9: Melbourne Red (TABES FLAMA 6.5) | C9: 0 | D9: 0 | E9: 0 | F9: 0 | G9: 0 | H9: 0 | I9: 0 | J9: 0 | K9: =SUM(C9:I9) -> 0 | M9: 0 | N9: 0 | O9: 0 | P9: =K9+M9+N9+O9 -> 0
C10: 0 | D10: 0 | E10: 0 | F10: 0 | G10: 0 | H10: 0 | I10: 0 | J10: 0 | K10: =SUM(C10:I10) -> 0 | M10: 0 | N10: 0 | O10: 0 | P10: =K10+M10+N10+O10 -> 0
B11: Melbourne Red (TABES FLAMA 6.5 AAE) | C11: 0 | D11: 0 | E11: 0 | F11: 0 | G11: 0 | H11: 0 | I11: 0 | J11: 0 | K11: =SUM(C11:J11) -> 0 | M11: 0 | N11: 0 | O11: 0 | P11: =K11+M11+N11+O11 -> 0
C12: 0 | D12: 0 | E12: 0 | F12: 0 | G12: 0 | H12: 0 | I12: 0 | J12: 0 | K12: =SUM(C12:J12) -> 0 | M12: 0 | N12: 0 | O12: 0 | P12: =K12+M12+N12+O12 -> 0
B13: Melbourne Gold (TABES FLAMA 6.5) | C13: 0 | D13: 0 | E13: 0 | F13: 0 | G13: 0 | H13: 0 | I13: 0 | J13: 0 | K13: =SUM(C13:J13) -> 0 | M13: 0 | N13: 0 | O13: 0 | P13: =K13+M13+N13+O13 -> 0
C14: 0 | D14: 0 | E14: 0 | F14: 0 | G14: 0 | H14: 0 | I14: 0 | J14: 0 | K14: =SUM(C14:J14) -> 0 | M14: 0 | N14: 0 | O14: 0 | P14: =K14+M14+N14+O14 -> 0
B15: Melbourne Gold (TABES FLAMA 6.5 AAE) | C15: 0 | D15: 0 | E15: 0 | F15: 0 | G15: 0 | H15: 0 | I15: 0 | J15: 0 | K15: =SUM(C15:J15) -> 0 | M15: 0 | N15: 0 | O15: 0 | P15: =K15+M15+N15+O15 -> 0
C16: 0 | D16: 0 | E16: 0 | F16: 0 | G16: 0 | H16: 0 | I16: 0 | J16: 0 | K16: =SUM(C16:J16) -> 0 | M16: 0 | N16: 0 | O16: 0 | P16: =K16+M16+N16+O16 -> 0
B17: Melbourne Mint (TABES FLAMA 6.5) | C17: 0 | D17: 0 | E17: 0 | F17: 0 | G17: 0 | H17: 0 | I17: 0 | J17: 0 | K17: =SUM(C17:J17) -> 0 | M17: 0 | N17: 0 | O17: 0 | P17: =K17+M17+N17+O17 -> 0
C18: 0 | D18: 0 | E18: 0 | F18: 0 | G18: 0 | H18: 0 | I18: 0 | J18: 0 | K18: =SUM(C18:J18) -> 0 | M18: 0 | N18: 0 | O18: 0 | P18: =K18+M18+N18+O18 -> 0
B19: Melbourne Mint (TABES FLAMA 6.5 AAE) | C19: 0 | D19: 0 | E19: 0 | F19: 0 | G19: 0 | H19: 0 | I19: 0 | J19: 0 | K19: =SUM(C19:J19) -> 0 | M19: 0 | N19: 0 | O19: 0 | P19: =K19+M19+N19+O19 -> 0
C20: 0 | D20: 0 | E20: 0 | F20: 0 | G20: 0 | H20: 0 | I20: 0 | J20: 0 | K20: =SUM(C20:J20) -> 0 | M20: 0 | N20: 0 | O20: 0 | P20: =K20+M20+N20+O20 -> 0
B21: Mill (TABES FLAMA 6.5) | C21: 1200 | D21: 1200 | E21: 1200 | F21: 0 | G21: 0 | H21: 0 | I21: 0 | J21: 0 | K21: =SUM(C21:J21) -> 3600 | M21: 0 | N21: 0 | O21: 0 | P21: =K21+M21+N21+O21 -> 3600
C22: 0 | D22: 0 | E22: 0 | F22: 0 | G22: 0 | H22: 0 | I22: 0 | J22: 0 | K22: =SUM(C22:J22) -> 0 | M22: 0 | N22: 0 | O22: 0 | P22: =K22+M22+N22+O22 -> 0
B23: Mill (TABES FLAMA 6.5 AAE) | C23: 0 | D23: 0 | E23: 0 | F23: 0 | G23: 0 | H23: 0 | I23: 0 | J23: 0 | K23: =SUM(C23:J23) -> 0 | M23: 0 | N23: 0 | O23: 0 | P23: =K23+M23+N23+O23 -> 0
C24: 0 | D24: 0 | E24: 0 | F24: 0 | G24: 0 | H24: 0 | I24: 0 | J24: 0 | K24: =SUM(C24:J24) -> 0 | M24: 0 | N24: 0 | O24: 0 | P24: =K24+M24+N24+O24 -> 0
B25: Mill Mint (TABES FLAMA 6.5) | C25: 0 | D25: 0 | E25: 0 | F25: 0 | G25: 0 | H25: 0 | I25: 0 | J25: 0 | K25: =SUM(C25:J25) -> 0 | M25: 0 | N25: 0 | O25: 0 | P25: =K25+M25+N25+O25 -> 0
C26: 0 | D26: 0 | E26: 0 | F26: 0 | G26: 0 | H26: 0 | I26: 0 | J26: 0 | K26: =SUM(C26:J26) -> 0 | M26: 0 | N26: 0 | O26: 0 | P26: =K26+M26+N26+O26 -> 0
B27: Mill Mint (TABES FLAMA 6.5 AAE) | C27: 0 | D27: 0 | E27: 0 | F27: 0 | G27: 0 | H27: 0 | I27: 0 | J27: 0 | K27: =SUM(C27:J27) -> 0 | M27: 0 | N27: 0 | O27: 0 | P27: =K27+M27+N27+O27 -> 0
C28: 0 | D28: 0 | E28: 0 | F28: 0 | G28: 0 | H28: 0 | I28: 0 | J28: 0 | K28: =SUM(C28:J28) -> 0 | M28: 0 | N28: 0 | O28: 0 | P28: =K28+M28+N28+O28 -> 0
B29: Bold Full (TABES FLAMA 6.5) | C29: 0 | D29: 0 | E29: 0 | F29: 1200 | G29: 1200 | H29: 0 | I29: 0 | J29: 0 | K29: =SUM(C29:J29) -> 2400 | M29: 0 | N29: 0 | O29: 0 | P29: =K29+M29+N29+O29 -> 2400
C30: 0 | D30: 0 | E30: 0 | F30: 0 | G30: 0 | H30: 0 | I30: 0 | J30: 0 | K30: =SUM(C30:J30) -> 0 | M30: 0 | N30: 0 | O30: 0 | P30: =K30+M30+N30+O30 -> 0
B31: Bold Full (TABES FLAMA 6.5 AAE) | C31: 0 | D31: 0 | E31: 0 | F31: 0 | G31: 0 | H31: 0 | I31: 0 | J31: 0 | K31: =SUM(C31:J31) -> 0 | M31: 0 | N31: 0 | O31: 0 | P31: =K31+M31+N31+O31 -> 0
C32: 0 | D32: 0 | E32: 0 | F32: 0 | G32: 0 | H32: 0 | I32: 0 | J32: 0 | K32: =SUM(C32:J32) -> 0 | M32: 0 | N32: 0 | O32: 0 | P32: =K32+M32+N32+O32 -> 0
B33: Bold Mint (TABES FLAMA 6.5) | C33: 0 | D33: 0 | E33: 0 | F33: 0 | G33: 0 | H33: 0 | I33: 0 | J33: 0 | K33: =SUM(C33:J33) -> 0 | M33: 0 | N33: 0 | O33: 0 | P33: =K33+M33+N33+O33 -> 0
C34: 0 | D34: 0 | E34: 0 | F34: 0 | G34: 0 | H34: 0 | I34: 0 | J34: 0 | K34: =SUM(C34:J34) -> 0 | M34: 0 | N34: 0 | O34: 0 | P34: =K34+M34+N34+O34 -> 0
B35: Bold Mint (TABES FLAMA 6.5 AAE) | C35: 0 | D35: 0 | E35: 0 | F35: 0 | G35: 0 | H35: 0 | I35: 0 | J35: 0 | K35: =SUM(C35:J35) -> 0 | M35: 0 | N35: 0 | O35: 0 | P35: =K35+M35+N35+O35 -> 0
C36: 0 | D36: 0 | E36: 0 | F36: 0 | G36: 0 | H36: 0 | I36: 0 | J36: 0 | K36: =SUM(C36:J36) -> 0 | M36: 0 | N36: 0 | O36: 0 | P36: =K36+M36+N36+O36 -> 0
B37: Sub total Ks (TABES FLAMA 6.5) | C37: =C9+C13+C17+C21+C29+C33+C25 -> 1200 | D37: =D9+D13+D17+D21+D29+D33+D25 -> 1200 | E37: =E9+E13+E17+E21+E29+E33+E25 -> 1200 | F37: =F9+F13+F17+F21+F29+F33+F25 -> 1200 | G37: =G9+G13+G17+G21+G29+G33+G25 -> 1200 | H37: =H9+H13+H17+H21+H29+H33+H25 -> 0 | I37: =I9+I13+I17+I21+I29+I33+I25 -> 0 | J37: =J9+J13+J17+J21+J29+J33+J25 -> 0 | K37: =K9+K13+K17+K21+K29+K33+K25 -> 6000 | M37: =M9+M13+M17+M21+M29+M33+M25 -> 0 | N37: =N9+N13+N17+N21+N29+N33+N25 -> 0 | O37: =O9+O13+O17+O21+O29+O33+O25 -> 0 | P37: =P9+P13+P17+P21+P29+P33+P25 -> 6000
C38: =C10+C14+C18+C22+C30+C34+C26 -> 0 | D38: =D10+D14+D18+D22+D30+D34+D26 -> 0 | E38: =E10+E14+E18+E22+E30+E34+E26 -> 0 | F38: =F10+F14+F18+F22+F30+F34+F26 -> 0 | G38: =G10+G14+G18+G22+G30+G34+G26 -> 0 | H38: =H10+H14+H18+H22+H30+H34+H26 -> 0 | I38: =I10+I14+I18+I22+I30+I34+I26 -> 0 | J38: =J10+J14+J18+J22+J30+J34+J26 -> 0 | K38: =K10+K14+K18+K22+K30+K34+K26 -> 0 | M38: =M10+M14+M18+M22+M30+M34+M26 -> 0 | N38: =N10+N14+N18+N22+N30+N34+N26 -> 0 | O38: =O10+O14+O18+O22+O30+O34+O26 -> 0 | P38: =P10+P14+P18+P22+P30+P34+P26 -> 0
B39: Sub total Ks (TABES FLAMA 6.5 AAE) | C39: =C11+C15+C19+C23+C31+C35+C27 -> 0 | D39: =D11+D15+D19+D23+D31+D35+D27 -> 0 | E39: =E11+E15+E19+E23+E31+E35+E27 -> 0 | F39: =F11+F15+F19+F23+F31+F35+F27 -> 0 | G39: =G11+G15+G19+G23+G31+G35+G27 -> 0 | H39: =H11+H15+H19+H23+H31+H35+H27 -> 0 | I39: =I11+I15+I19+I23+I31+I35+I27 -> 0 | J39: =J11+J15+J19+J23+J31+J35+J27 -> 0 | K39: =K11+K15+K19+K23+K31+K35+K27 -> 0 | M39: =M11+M15+M19+M23+M31+M35+M27 -> 0 | N39: =N11+N15+N19+N23+N31+N35+N27 -> 0 | O39: =O11+O15+O19+O23+O31+O35+O27 -> 0 | P39: =P11+P15+P19+P23+P31+P35+P27 -> 0
C40: =C12+C16+C20+C24+C32+C36+C28 -> 0 | D40: =D12+D16+D20+D24+D32+D36+D28 -> 0 | E40: =E12+E16+E20+E24+E32+E36+E28 -> 0 | F40: =F12+F16+F20+F24+F32+F36+F28 -> 0 | G40: =G12+G16+G20+G24+G32+G36+G28 -> 0 | H40: =H12+H16+H20+H24+H32+H36+H28 -> 0 | I40: =I12+I16+I20+I24+I32+I36+I28 -> 0 | J40: =J12+J16+J20+J24+J32+J36+J28 -> 0 | K40: =K12+K16+K20+K24+K32+K36+K28 -> 0 | M40: =M12+M16+M20+M24+M32+M36+M28 -> 0 | N40: =N12+N16+N20+N24+N32+N36+N28 -> 0 | O40: =O12+O16+O20+O24+O32+O36+O28 -> 0 | P40: =P12+P16+P20+P24+P32+P36+P28 -> 0
B41: Milenio Red (TABES FLAMA 6.5) | C41: 700 | D41: 700 | E41: 700 | F41: 500 | G41: 0 | H41: 0 | I41: 0 | J41: 0 | K41: =SUM(C41:J41) -> 2600 | M41: 0 | N41: 0 | O41: 0 | P41: =K41+M41+N41+O41 -> 2600
C42: 0 | D42: 0 | E42: 0 | F42: 0 | G42: 0 | H42: 0 | I42: 0 | J42: 0 | K42: =SUM(C42:J42) -> 0 | M42: 0 | N42: 0 | O42: 0 | P42: =K42+M42+N42+O42 -> 0
B43: Milenio Red (TABES FLAMA 6.5 AAE) | C43: 0 | D43: 0 | E43: 0 | F43: 0 | G43: 0 | H43: 0 | I43: 0 | J43: 0 | K43: =SUM(C43:J43) -> 0 | M43: 0 | N43: 0 | O43: 0 | P43: =K43+M43+N43+O43 -> 0
...

Sheet Gráfico_Plan

Sheet Stock insumos
A1: Materiales | C1: Rendimiento | H1: Cantidad Mat actual | K1: Capacidad de Producción | M1: Estimación en días | P1: Planificación
A2: Texto Breve | B2: Descripción | C2: Cant | D2: Unidad | E2: Resultado | F2: Unidad | H2: Cantidad | I2: Unidad | K2: Cajas PT | M2: Cajas PT diarias | N2: Cantidad de días | P2: Lunes | Q2: Resto | R2: Resto días | S2: Martes | T2: Resto | U2: Resto días | V2: Miércoles | W2: Resto | X2: Resto días | Y2: Jueves | Z2: Resto | AA2: Resto días | AB2: Viernes | AC2: Resto | AD2: Resto días | AE2: Sábado | AF2: Resto | AG2: Resto días | AH2: Domingo | AI2: Resto | AJ2: Resto días | AK2: Semana 2 | AL2: Resto S2 | AM2: Resto días | AN2: Semana 3 | AO2: Resto S3 | AP2: Resto días | AQ2: Semana 4 | AR2: Resto S4 | AS2: Resto días
A3: Papel Boquilla - MELBOURNE RED | B3: Papel Boquilla - MELBOURNE RED | C3: 1 | D3: BOBINA | E3: 40 | F3: CAJA PT | H3: 273 | I3: BOBINA | K3: =(H3*E3)/C3 -> 10920 | M3: 250 | N3: =K3/M3 -> 43.68 | P3: ='Plan - Semanal'!$C$9+'Plan - Semanal'!$C$10+'Plan - Semanal'!$C$11+'Plan - Semanal'!$C$12 -> 0 | Q3: =K3-P3 -> 10920 | R3: =Q3/$M3 -> 43.68 | S3: ='Plan - Semanal'!$D$9+'Plan - Semanal'!$D$10+'Plan - Semanal'!$D$11+'Plan - Semanal'!$D$12 -> 0 | T3: =Q3-S3 -> 10920 | U3: =T3/$M3 -> 43.68 | V3: ='Plan - Semanal'!$E$9+'Plan - Semanal'!$E$10+'Plan - Semanal'!$E$11+'Plan - Semanal'!$E$12 -> 0 | W3: =T3-V3 -> 10920 | X3: =W3/$M3 -> 43.68 | Y3: ='Plan - Semanal'!$F$9+'Plan - Semanal'!$F$10+'Plan - Semanal'!$F$11+'Plan - Semanal'!$F$12 -> 0 | Z3: =W3-Y3 -> 10920 | AA3: =Z3/$M3 -> 43.68 | AB3: ='Plan - Semanal'!$G$9+'Plan - Semanal'!$G$10+'Plan - Semanal'!$G$11+'Plan - Semanal'!$G$12 -> 0 | AC3: =Z3-AB3 -> 10920 | AD3: =AC3/$M3 -> 43.68 | AE3: ='Plan - Semanal'!$H$9+'Plan - Semanal'!$H$10+'Plan - Semanal'!$H$11+'Plan - Semanal'!$H$12 -> 0 | AF3: =AC3-AE3 -> 10920 | AG3: =AF3/$M3 -> 43.68 | AH3: ='Plan - Semanal'!$I$9+'Plan - Semanal'!$I$10+'Plan - Semanal'!$I$11+'Plan - Semanal'!$I$12 -> 0 | AI3: =AF3-AH3 -> 10920 | AJ3: =AI3/$M3 -> 43.68 | AK3: ='Plan - Semanal'!$M$9+'Plan - Semanal'!$M$10+'Plan - Semanal'!$M$11+'Plan - Semanal'!$M$12 -> 0 | AL3: =AI3-AK3 -> 10920 | AM3: =AL3/$M3 -> 43.68 | AN3: ='Plan - Semanal'!$N$9+'Plan - Semanal'!$N$10+'Plan - Semanal'!$N$11+'Plan - Semanal'!$N$12 -> 0 | AO3: =AL3-AN3 -> 10920 | AP3: =AO3/$M3 -> 43.68 | AQ3: ='Plan - Semanal'!$O$9+'Plan - Semanal'!$O$10+'Plan - Semanal'!$O$11+'Plan - Semanal'!$O$12 -> 0 | AR3: =AO3-AQ3 -> 10920 | AS3: =AR3/M3 -> 43.68
A4: Papel Boquilla - MELBOURNE GOLD | B4: Papel Boquilla - MELBOURNE GOLD | C4: 1 | D4: BOBINA | E4: 40 | F4: CAJA PT | H4: 9 | I4: BOBINA | K4: =(H4*E4)/C4 -> 360 | M4: 35 | N4: =K4/M4 -> 10.285714 | P4: ='Plan - Semanal'!$C$13+'Plan - Semanal'!$C$14+'Plan - Semanal'!$C$15+'Plan - Semanal'!$C$16 -> 0 | Q4: =K4-P4 -> 360 | R4: =Q4/$M4 -> 10.285714 | S4: ='Plan - Semanal'!$D$13+'Plan - Semanal'!$D$14+'Plan - Semanal'!$D$15+'Plan - Semanal'!$D$16 -> 0 | T4: =Q4-S4 -> 360 | U4: =T4/$M4 -> 10.285714 | V4: ='Plan - Semanal'!$E$13+'Plan - Semanal'!$E$14+'Plan - Semanal'!$E$15+'Plan - Semanal'!$E$16 -> 0 | W4: =T4-V4 -> 360 | X4: =W4/$M4 -> 10.285714 | Y4: ='Plan - Semanal'!$F$13+'Plan - Semanal'!$F$14+'Plan - Semanal'!$F$15+'Plan - Semanal'!$F$16 -> 0 | Z4: =W4-Y4 -> 360 | AA4: =Z4/$M4 -> 10.285714 | AB4: ='Plan - Semanal'!$G$13+'Plan - Semanal'!$G$14+'Plan - Semanal'!$G$15+'Plan - Semanal'!$G$16 -> 0 | AC4: =Z4-AB4 -> 360 | AD4: =AC4/$M4 -> 10.285714 | AE4: =+'Plan - Semanal'!$H$13+'Plan - Semanal'!$H$14+'Plan - Semanal'!$H$15+'Plan - Semanal'!$H$16 -> 0 | AF4: =AC4-AE4 -> 360 | AG4: =AF4/$M4 -> 10.285714 | AH4: =+'Plan - Semanal'!$I$13+'Plan - Semanal'!$I$14+'Plan - Semanal'!$I$15+'Plan - Semanal'!$I$16 -> 0 | AI4: =AF4-AH4 -> 360 | AJ4: =AI4/$M4 -> 10.285714 | AK4: =+'Plan - Semanal'!$M$13+'Plan - Semanal'!$M$14+'Plan - Semanal'!$M$15+'Plan - Semanal'!$M$16 -> 0 | AL4: =AI4-AK4 -> 360 | AM4: =AL4/$M4 -> 10.285714 | AN4: =+'Plan - Semanal'!$N$13+'Plan - Semanal'!$N$14+'Plan - Semanal'!$N$15+'Plan - Semanal'!$N$16 -> 0 | AO4: =AL4-AN4 -> 360 | AP4: =AO4/$M4 -> 10.285714 | AQ4: =+'Plan - Semanal'!$O$13+'Plan - Semanal'!$O$14+'Plan - Semanal'!$O$15+'Plan - Semanal'!$O$16 -> 0 | AR4: =AO4-AQ4 -> 360 | AS4: =AR4/M4 -> 10.285714
A5: Papel Boquilla - MELBOURNE MINT | B5: Papel Boquilla - MELBOURNE MINT | C5: 1 | D5: BOBINA | E5: 40 | F5: CAJA PT | H5: 32 | I5: BOBINA | K5: =(H5*E5)/C5 -> 1280 | M5: 20 | N5: =K5/M5 -> 64 | P5: =+'Plan - Semanal'!$C$17+'Plan - Semanal'!$C$18+'Plan - Semanal'!$C$19+'Plan - Semanal'!$C$20 -> 0 | Q5: =K5-P5 -> 1280 | R5: =Q5/$M5 -> 64 | S5: =+'Plan - Semanal'!$D$17+'Plan - Semanal'!$D$18+'Plan - Semanal'!$D$19+'Plan - Semanal'!$D$20 -> 0 | T5: =Q5-S5 -> 1280 | U5: =T5/$M5 -> 64 | V5: =+'Plan - Semanal'!$E$17+'Plan - Semanal'!$E$18+'Plan - Semanal'!$E$19+'Plan - Semanal'!$E$20 -> 0 | W5: =T5-V5 -> 1280 | X5: =W5/$M5 -> 64 | Y5: =+'Plan - Semanal'!$F$17+'Plan - Semanal'!$F$18+'Plan - Semanal'!$F$19+'Plan - Semanal'!$F$20 -> 0 | Z5: =W5-Y5 -> 1280 | AA5: =Z5/$M5 -> 64 | AB5: =+'Plan - Semanal'!$G$17+'Plan - Semanal'!$G$18+'Plan - Semanal'!$G$19+'Plan - Semanal'!$G$20 -> 0 | AC5: =Z5-AB5 -> 1280 | AD5: =AC5/$M5 -> 64 | AE5: =+'Plan - Semanal'!$H$17+'Plan - Semanal'!$H$18+'Plan - Semanal'!$H$19+'Plan - Semanal'!$H$20 -> 0 | AF5: =AC5-AE5 -> 1280 | AG5: =AF5/$M5 -> 64 | AH5: =+'Plan - Semanal'!$I$17+'Plan - Semanal'!$I$18+'Plan - Semanal'!$I$19+'Plan - Semanal'!$I$20 -> 0 | AI5: =AF5-AH5 -> 1280 | AJ5: =AI5/$M5 -> 64 | AK5: =+'Plan - Semanal'!$M$17+'Plan - Semanal'!$M$18+'Plan - Semanal'!$M$19+'Plan - Semanal'!$M$20 -> 0 | AL5: =AI5-AK5 -> 1280 | AM5: =AL5/$M5 -> 64 | AN5: =+'Plan - Semanal'!$N$17+'Plan - Semanal'!$N$18+'Plan - Semanal'!$N$19+'Plan - Semanal'!$N$20 -> 0 | AO5: =AL5-AN5 -> 1280 | AP5: =AO5/$M5 -> 64 | AQ5: =+'Plan - Semanal'!$O$17+'Plan - Semanal'!$O$18+'Plan - Semanal'!$O$19+'Plan - Semanal'!$O$20 -> 0 | AR5: =AO5-AQ5 -> 1280 | AS5: =AR5/M5 -> 64
A6: Papel Boquilla - MILL | B6: Papel Boquilla - MILL | C6: 1 | D6: BOBINA | E6: 40 | F6: CAJA PT | H6: 105 | I6: BOBINA | K6: =(H6*E6)/C6 -> 4200 | M6: 430 | N6: =K6/M6 -> 9.7674419 | P6: =+'Plan - Semanal'!$C$21+'Plan - Semanal'!$C$22+'Plan - Semanal'!$C$23+'Plan - Semanal'!$C$24 -> 1200 | Q6: =K6-P6 -> 3000 | R6: =Q6/$M6 -> 6.9767442 | S6: =+'Plan - Semanal'!$D$21+'Plan - Semanal'!$D$22+'Plan - Semanal'!$D$23+'Plan - Semanal'!$D$24 -> 1200 | T6: =Q6-S6 -> 1800 | U6: =T6/$M6 -> 4.1860465 | V6: =+'Plan - Semanal'!$E$21+'Plan - Semanal'!$E$22+'Plan - Semanal'!$E$23+'Plan - Semanal'!$E$24 -> 1200 | W6: =T6-V6 -> 600 | X6: =W6/$M6 -> 1.3953488 | Y6: =+'Plan - Semanal'!$F$21+'Plan - Semanal'!$F$22+'Plan - Semanal'!$F$23+'Plan - Semanal'!$F$24 -> 0 | Z6: =W6-Y6 -> 600 | AA6: =Z6/$M6 -> 1.3953488 | AB6: =+'Plan - Semanal'!$G$21+'Plan - Semanal'!$G$22+'Plan - Semanal'!$G$23+'Plan - Semanal'!$G$24 -> 0 | AC6: =Z6-AB6 -> 600 | AD6: =AC6/$M6 -> 1.3953488 | AE6: =+'Plan - Semanal'!$H$21+'Plan - Semanal'!$H$22+'Plan - Semanal'!$H$23+'Plan - Semanal'!$H$24 -> 0 | AF6: =AC6-AE6 -> 600 | AG6: =AF6/$M6 -> 1.3953488 | AH6: =+'Plan - Semanal'!$I$21+'Plan - Semanal'!$I$22+'Plan - Semanal'!$I$23+'Plan - Semanal'!$I$24 -> 0 | AI6: =AF6-AH6 -> 600 | AJ6: =AI6/$M6 -> 1.3953488 | AK6: =+'Plan - Semanal'!$M$21+'Plan - Semanal'!$M$22+'Plan - Semanal'!$M$23+'Plan - Semanal'!$M$24 -> 0 | AL6: =AI6-AK6 -> 600 | AM6: =AL6/$M6 -> 1.3953488 | AN6: =+'Plan - Semanal'!$N$21+'Plan - Semanal'!$N$22+'Plan - Semanal'!$N$23+'Plan - Semanal'!$N$24 -> 0 | AO6: =AL6-AN6 -> 600 | AP6: =AO6/$M6 -> 1.3953488 | AQ6: =+'Plan - Semanal'!$O$21+'Plan - Semanal'!$O$22+'Plan - Semanal'!$O$23+'Plan - Semanal'!$O$24 -> 0 | AR6: =AO6-AQ6 -> 600 | AS6: =AR6/M6 -> 1.3953488
A7: Papel Boquilla - MILL MINT | B7: Papel Boquilla - MILL MINT | C7: 1 | D7: BOBINA | E7: 40 | F7: CAJA PT | H7: 90 | I7: BOBINA | K7: =(H7*E7)/C7 -> 3600 | M7: 0 | N7: =K7/M7 -> #DIV/0! | P7: =+'Plan - Semanal'!C49+'Plan - Semanal'!C50+'Plan - Semanal'!C51+'Plan - Semanal'!C52 -> 0 | Q7: =K7-P7 -> 3600 | R7: =Q7/$M7 -> #DIV/0! | S7: =+'Plan - Semanal'!D49+'Plan - Semanal'!D50+'Plan - Semanal'!D51+'Plan - Semanal'!D52 -> 0 | T7: =Q7-S7 -> 3600 | U7: =T7/$M7 -> #DIV/0! | V7: =+'Plan - Semanal'!E49+'Plan - Semanal'!E50+'Plan - Semanal'!E51+'Plan - Semanal'!E52 -> 0 | W7: =T7-V7 -> 3600 | X7: =W7/$M7 -> #DIV/0! | Y7: =+'Plan - Semanal'!F49+'Plan - Semanal'!F50+'Plan - Semanal'!F51+'Plan - Semanal'!F52 -> 0 | Z7: =W7-Y7 -> 3600 | AA7: =Z7/$M7 -> #DIV/0! | AB7: =+'Plan - Semanal'!G49+'Plan - Semanal'!G50+'Plan - Semanal'!G51+'Plan - Semanal'!G52 -> 0 | AC7: =Z7-AB7 -> 3600 | AD7: =AC7/$M7 -> #DIV/0! | AE7: =+'Plan - Semanal'!H49+'Plan - Semanal'!H50+'Plan - Semanal'!H51+'Plan - Semanal'!H52 -> 0 | AF7: =AC7-AE7 -> 3600 | AG7: =AF7/$M7 -> #DIV/0! | AH7: =+'Plan - Semanal'!I49+'Plan - Semanal'!I50+'Plan - Semanal'!I51+'Plan - Semanal'!I52 -> 0 | AI7: =AF7-AH7 -> 3600 | AJ7: =AI7/$M7 -> #DIV/0! | AK7: =+'Plan - Semanal'!M49+'Plan - Semanal'!M50+'Plan - Semanal'!M51+'Plan - Semanal'!M52 -> 0 | AL7: =AI7-AK7 -> 3600 | AM7: =AL7/$M7 -> #DIV/0! | AN7: =+'Plan - Semanal'!N49+'Plan - Semanal'!N50+'Plan - Semanal'!N51+'Plan - Semanal'!N52 -> 0 | AO7: =AL7-AN7 -> 3600 | AP7: =AO7/$M7 -> #DIV/0! | AQ7: =+'Plan - Semanal'!O49+'Plan - Semanal'!O50+'Plan - Semanal'!O51+'Plan - Semanal'!O52 -> 0 | AR7: =AO7-AQ7 -> 3600 | AS7: =AR7/M7 -> #DIV/0!
A8: Papel Boquilla - BOLD FULL | B8: Papel Boquilla - BOLD FULL | C8: 1 | D8: BOBINA | E8: 40 | F8: CAJA PT | H8: 121 | I8: BOBINA | K8: =(H8*E8)/C8 -> 4840 | M8: 465 | N8: =K8/M8 -> 10.408602 | P8: =+'Plan - Semanal'!$C$29+'Plan - Semanal'!$C$30+'Plan - Semanal'!$C$31+'Plan - Semanal'!$C$32 -> 0 | Q8: =K8-P8 -> 4840 | R8: =Q8/$M8 -> 10.408602 | S8: =+'Plan - Semanal'!$D$29+'Plan - Semanal'!$D$30+'Plan - Semanal'!$D$31+'Plan - Semanal'!$D$32 -> 0 | T8: =Q8-S8 -> 4840 | U8: =T8/$M8 -> 10.408602 | V8: =+'Plan - Semanal'!$E$29+'Plan - Semanal'!$E$30+'Plan - Semanal'!$E$31+'Plan - Semanal'!$E$32 -> 0 | W8: =T8-V8 -> 4840 | X8: =W8/$M8 -> 10.408602 | Y8: =+'Plan - Semanal'!$F$29+'Plan - Semanal'!$F$30+'Plan - Semanal'!$F$31+'Plan - Semanal'!$F$32 -> 1200 | Z8: =W8-Y8 -> 3640 | AA8: =Z8/$M8 -> 7.827957 | AB8: =+'Plan - Semanal'!$G$29+'Plan - Semanal'!$G$30+'Plan - Semanal'!$G$31+'Plan - Semanal'!$G$32 -> 1200 | AC8: =Z8-AB8 -> 2440 | AD8: =AC8/$M8 -> 5.2473118 | AE8: =+'Plan - Semanal'!$H$29+'Plan - Semanal'!$H$30+'Plan - Semanal'!$H$31+'Plan - Semanal'!$H$32 -> 0 | AF8: =AC8-AE8 -> 2440 | AG8: =AF8/$M8 -> 5.2473118 | AH8: =+'Plan - Semanal'!$I$29+'Plan - Semanal'!$I$30+'Plan - Semanal'!$I$31+'Plan - Semanal'!$I$32 -> 0 | AI8: =AF8-AH8 -> 2440 | AJ8: =AI8/$M8 -> 5.2473118 | AK8: =+'Plan - Semanal'!$M$29+'Plan - Semanal'!$M$30+'Plan - Semanal'!$M$31+'Plan - Semanal'!$M$32 -> 0 | AL8: =AI8-AK8 -> 2440 | AM8: =AL8/$M8 -> 5.2473118 | AN8: =+'Plan - Semanal'!$N$29+'Plan - Semanal'!$N$30+'Plan - Semanal'!$N$31+'Plan - Semanal'!$N$32 -> 0 | AO8: =AL8-AN8 -> 2440 | AP8: =AO8/$M8 -> 5.2473118 | AQ8: =+'Plan - Semanal'!$O$29+'Plan - Semanal'!$O$30+'Plan - Semanal'!$O$31+'Plan - Semanal'!$O$32 -> 0 | AR8: =AO8-AQ8 -> 2440 | AS8: =AR8/M8 -> 5.2473118
A9: Papel Boquilla - BOLD MINT | B9: Papel Boquilla - BOLD MINT | C9: 1 | D9: BOBINA | E9: 40 | F9: CAJA PT | H9: 90 | I9: BOBINA | K9: =(H9*E9)/C9 -> 3600 | M9: 0 | N9: =K9/M9 -> #DIV/0! | P9: =+'Plan - Semanal'!$C$33+'Plan - Semanal'!$C$34+'Plan - Semanal'!$C$35+'Plan - Semanal'!$C$36 -> 0 | Q9: =K9-P9 -> 3600 | R9: =Q9/$M9 -> #DIV/0! | S9: =+'Plan - Semanal'!$D$33+'Plan - Semanal'!$D$34+'Plan - Semanal'!$D$35+'Plan - Semanal'!$D$36 -> 0 | T9: =Q9-S9 -> 3600 | U9: =T9/$M9 -> #DIV/0! | V9: =+'Plan - Semanal'!$E$33+'Plan - Semanal'!$E$34+'Plan - Semanal'!$E$35+'Plan - Semanal'!$E$36 -> 0 | W9: =T9-V9 -> 3600 | X9: =W9/$M9 -> #DIV/0! | Y9: =+'Plan - Semanal'!$F$33+'Plan - Semanal'!$F$34+'Plan - Semanal'!$F$35+'Plan - Semanal'!$F$36 -> 0 | Z9: =W9-Y9 -> 3600 | AA9: =Z9/$M9 -> #DIV/0! | AB9: =+'Plan - Semanal'!$G$33+'Plan - Semanal'!$G$34+'Plan - Semanal'!$G$35+'Plan - Semanal'!$G$36 -> 0 | AC9: =Z9-AB9 -> 3600 | AD9: =AC9/$M9 -> #DIV/0! | AE9: =+'Plan - Semanal'!$H$33+'Plan - Semanal'!$H$34+'Plan - Semanal'!$H$35+'Plan - Semanal'!$H$36 -> 0 | AF9: =AC9-AE9 -> 3600 | AG9: =AF9/$M9 -> #DIV/0! | AH9: =+'Plan - Semanal'!$I$33+'Plan - Semanal'!$I$34+'Plan - Semanal'!$I$35+'Plan - Semanal'!$I$36 -> 0 | AI9: =AF9-AH9 -> 3600 | AJ9: =AI9/$M9 -> #DIV/0! | AK9: =+'Plan - Semanal'!$M$33+'Plan - Semanal'!$M$34+'Plan - Semanal'!$M$35+'Plan - Semanal'!$M$36 -> 0 | AL9: =AI9-AK9 -> 3600 | AM9: =AL9/$M9 -> #DIV/0! | AN9: =+'Plan - Semanal'!$N$33+'Plan - Semanal'!$N$34+'Plan - Semanal'!$N$35+'Plan - Semanal'!$N$36 -> 0 | AO9: =AL9-AN9 -> 3600 | AP9: =AO9/$M9 -> #DIV/0! | AQ9: =+'Plan - Semanal'!$O$33+'Plan - Semanal'!$O$34+'Plan - Semanal'!$O$35+'Plan - Semanal'!$O$36 -> 0 | AR9: =AO9-AQ9 -> 3600 | AS9: =AR9/M9 -> #DIV/0!
A10: Papel Boquilla - MILENIO RED | B10: Papel Boquilla - MILENIO RED | C10: 1 | D10: BOBINA | E10: 40 | F10: CAJA PT | H10: 64 | I10: BOBINA | K10: =(H10*E10)/C10 -> 2560 | M10: 240 | N10: =K10/M10 -> 10.666667 | P10: ='Plan - Semanal'!$C$41+'Plan - Semanal'!$C$42+'Plan - Semanal'!$C$43+'Plan - Semanal'!$C$44 -> 700 | Q10: =K10-P10 -> 1860 | R10: =Q10/$M10 -> 7.75 | S10: =+'Plan - Semanal'!$D$41+'Plan - Semanal'!$D$42+'Plan - Semanal'!$D$43+'Plan - Semanal'!$D$44 -> 700 | T10: =Q10-S10 -> 1160 | U10: =T10/$M10 -> 4.8333333 | V10: =+'Plan - Semanal'!$E$41+'Plan - Semanal'!$E$42+'Plan - Semanal'!$E$43+'Plan - Semanal'!$E$44 -> 700 | W10: =T10-V10 -> 460 | X10: =W10/$M10 -> 1.9166667 | Y10: =+'Plan - Semanal'!$F$41+'Plan - Semanal'!$F$42+'Plan - Semanal'!$F$43+'Plan - Semanal'!$F$44 -> 500 | Z10: =W10-Y10 -> -40 | AA10: =Z10/$M10 -> -0.16666667 | AB10: =+'Plan - Semanal'!$G$41+'Plan - Semanal'!$G$42+'Plan - Semanal'!$G$43+'Plan - Semanal'!$G$44 -> 0 | AC10: =Z10-AB10 -> -40 | AD10: =AC10/$M10 -> -0.16666667 | AE10: =+'Plan - Semanal'!$H$41+'Plan - Semanal'!$H$42+'Plan - Semanal'!$H$43+'Plan - Semanal'!$H$44 -> 0 | AF10: =AC10-AE10 -> -40 | AG10: =AF10/$M10 -> -0.16666667 | AH10: =+'Plan - Semanal'!$I$41+'Plan - Semanal'!$I$42+'Plan - Semanal'!$I$43+'Plan - Semanal'!$I$44 -> 0 | AI10: =AF10-AH10 -> -40 | AJ10: =AI10/$M10 -> -0.16666667 | AK10: =+'Plan - Semanal'!$M$41+'Plan - Semanal'!$M$42+'Plan - Semanal'!$M$43+'Plan - Semanal'!$M$44 -> 0 | AL10: =AI10-AK10 -> -40 | AM10: =AL10/$M10 -> -0.16666667 | AN10: =+'Plan - Semanal'!$N$41+'Plan - Semanal'!$N$42+'Plan - Semanal'!$N$43+'Plan - Semanal'!$N$44 -> 0 | AO10: =AL10-AN10 -> -40 | AP10: =AO10/$M10 -> -0.16666667 | AQ10: =+'Plan - Semanal'!$O$41+'Plan - Semanal'!$O$42+'Plan - Semanal'!$O$43+'Plan - Semanal'!$O$44 -> 0 | AR10: =AO10-AQ10 -> -40 | AS10: =AR10/M10 -> -0.16666667
A11: Papel Boquilla - MILENIO GOLD | B11: Papel Boquilla - MILENIO GOLD | C11: 1 | D11: BOBINA | E11: 40 | F11: CAJA PT | H11: 30 | I11: BOBINA | K11: =(H11*E11)/C11 -> 1200 | M11: 25 | N11: =K11/M11 -> 48 | P11: =+'Plan - Semanal'!$C$45+'Plan - Semanal'!$C$46+'Plan - Semanal'!$C$47+'Plan - Semanal'!$C$48 -> 0 | Q11: =K11-P11 -> 1200 | R11: =Q11/$M11 -> 48 | S11: =+'Plan - Semanal'!$D$45+'Plan - Semanal'!$D$46+'Plan - Semanal'!$D$47+'Plan - Semanal'!$D$48 -> 0 | T11: =Q11-S11 -> 1200 | U11: =T11/$M11 -> 48 | V11: =+'Plan - Semanal'!$E$45+'Plan - Semanal'!$E$46+'Plan - Semanal'!$E$47+'Plan - Semanal'!$E$48 -> 0 | W11: =T11-V11 -> 1200 | X11: =W11/$M11 -> 48 | Y11: =+'Plan - Semanal'!$F$45+'Plan - Semanal'!$F$46+'Plan - Semanal'!$F$47+'Plan - Semanal'!$F$48 -> 0 | Z11: =W11-Y11 -> 1200 | AA11: =Z11/$M11 -> 48 | AB11: =+'Plan - Semanal'!$G$45+'Plan - Semanal'!$G$46+'Plan - Semanal'!$G$47+'Plan - Semanal'!$G$48 -> 0 | AC11: =Z11-AB11 -> 1200 | AD11: =AC11/$M11 -> 48 | AE11: =+'Plan - Semanal'!$H$45+'Plan - Semanal'!$H$46+'Plan - Semanal'!$H$47+'Plan - Semanal'!$H$48 -> 0 | AF11: =AC11-AE11 -> 1200 | AG11: =AF11/$M11 -> 48 | AH11: =+'Plan - Semanal'!$I$45+'Plan - Semanal'!$I$46+'Plan - Semanal'!$I$47+'Plan - Semanal'!$I$48 -> 0 | AI11: =AF11-AH11 -> 1200 | AJ11: =AI11/$M11 -> 48 | AK11: =+'Plan - Semanal'!$M$45+'Plan - Semanal'!$M$46+'Plan - Semanal'!$M$47+'Plan - Semanal'!$M$48 -> 0 | AL11: =AI11-AK11 -> 1200 | AM11: =AL11/$M11 -> 48 | AN11: =+'Plan - Semanal'!$N$45+'Plan - Semanal'!$N$46+'Plan - Semanal'!$N$47+'Plan - Semanal'!$N$48 -> 0 | AO11: =AL11-AN11 -> 1200 | AP11: =AO11/$M11 -> 48 | AQ11: =+'Plan - Semanal'!$O$45+'Plan - Semanal'!$O$46+'Plan - Semanal'!$O$47+'Plan - Semanal'!$O$48 -> 0 | AR11: =AO11-AQ11 -> 1200 | AS11: =AR11/M11 -> 48
A12: Papel Boquilla - MILENIO MINT | B12: Papel Boquilla - MILENIO MINT | C12: 1 | D12: BOBINA | E12: 40 | F12: CAJA PT | H12: 66 | I12: BOBINA | K12: =(H12*E12)/C12 -> 2640 | M12: 35 | N12: =K12/M12 -> 75.428571 | P12: =+'Plan - Semanal'!$C$49+'Plan - Semanal'!$C$50+'Plan - Semanal'!$C$51+'Plan - Semanal'!$C$52 -> 0 | Q12: =K12-P12 -> 2640 | R12: =Q12/$M12 -> 75.428571 | S12: =+'Plan - Semanal'!$D$49+'Plan - Semanal'!$D$50+'Plan - Semanal'!$D$51+'Plan - Semanal'!$D$52 -> 0 | T12: =Q12-S12 -> 2640 | U12: =T12/$M12 -> 75.428571 | V12: =+'Plan - Semanal'!$E$49+'Plan - Semanal'!$E$50+'Plan - Semanal'!$E$51+'Plan - Semanal'!$E$52 -> 0 | W12: =T12-V12 -> 2640 | X12: =W12/$M12 -> 75.428571 | Y12: =+'Plan - Semanal'!$F$49+'Plan - Semanal'!$F$50+'Plan - Semanal'!$F$51+'Plan - Semanal'!$F$52 -> 0 | Z12: =W12-Y12 -> 2640 | AA12: =Z12/$M12 -> 75.428571 | AB12: =+'Plan - Semanal'!$G$49+'Plan - Semanal'!$G$50+'Plan - Semanal'!$G$51+'Plan - Semanal'!$G$52 -> 0 | AC12: =Z12-AB12 -> 2640 | AD12: =AC12/$M12 -> 75.428571 | AE12: =+'Plan - Semanal'!$H$49+'Plan - Semanal'!$H$50+'Plan - Semanal'!$H$51+'Plan - Semanal'!$H$52 -> 0 | AF12: =AC12-AE12 -> 2640 | AG12: =AF12/$M12 -> 75.428571 | AH12: =+'Plan - Semanal'!$I$49+'Plan - Semanal'!$I$50+'Plan - Semanal'!$I$51+'Plan - Semanal'!$I$52 -> 0 | AI12: =AF12-AH12 -> 2640 | AJ12: =AI12/$M12 -> 75.428571 | AK12: =+'Plan - Semanal'!$M$49+'Plan - Semanal'!$M$50+'Plan - Semanal'!$M$51+'Plan - Semanal'!$M$52 -> 0 | AL12: =AI12-AK12 -> 2640 | AM12: =AL12/$M12 -> 75.428571 | AN12: =+'Plan - Semanal'!$N$49+'Plan - Semanal'!$N$50+'Plan - Semanal'!$N$51+'Plan - Semanal'!$N$52 -> 0 | AO12: =AL12-AN12 -> 2640 | AP12: =AO12/$M12 -> 75.428571 | AQ12: =+'Plan - Semanal'!$O$49+'Plan - Semanal'!$O$50+'Plan - Semanal'!$O$51+'Plan - Semanal'!$O$52 -> 0 | AR12: =AO12-AQ12 -> 2640 | AS12: =AR12/M12 -> 75.428571
A13: Papel Boquilla - MILENIO ICERGY | B13: Papel Boquilla - MILENIO ICERGY | C13: 1 | D13: BOBINA | E13: 40 | F13: CAJA PT | H13: 154 | I13: BOBINA | K13: =(H13*E13)/C13 -> 6160 | M13: 200 | N13: =K13/M13 -> 30.8 | P13: =+'Plan - Semanal'!$C$53+'Plan - Semanal'!$C$54+'Plan - Semanal'!$C$55+'Plan - Semanal'!$C$56 -> 0 | Q13: =K13-P13 -> 6160 | R13: =Q13/$M13 -> 30.8 | S13: =+'Plan - Semanal'!$D$53+'Plan - Semanal'!$D$54+'Plan - Semanal'!$D$55+'Plan - Semanal'!$D$56 -> 0 | T13: =Q13-S13 -> 6160 | U13: =T13/$M13 -> 30.8 | V13: =+'Plan - Semanal'!$E$53+'Plan - Semanal'!$E$54+'Plan - Semanal'!$E$55+'Plan - Semanal'!$E$56 -> 0 | W13: =T13-V13 -> 6160 | X13: =W13/$M13 -> 30.8 | Y13: =+'Plan - Semanal'!$F$53+'Plan - Semanal'!$F$54+'Plan - Semanal'!$F$55+'Plan - Semanal'!$F$56 -> 0 | Z13: =W13-Y13 -> 6160 | AA13: =Z13/$M13 -> 30.8 | AB13: =+'Plan - Semanal'!$G$53+'Plan - Semanal'!$G$54+'Plan - Semanal'!$G$55+'Plan - Semanal'!$G$56 -> 0 | AC13: =Z13-AB13 -> 6160 | AD13: =AC13/$M13 -> 30.8 | AE13: =+'Plan - Semanal'!$H$53+'Plan - Semanal'!$H$54+'Plan - Semanal'!$H$55+'Plan - Semanal'!$H$56 -> 700 | AF13: =AC13-AE13 -> 5460 | AG13: =AF13/$M13 -> 27.3 | AH13: =+'Plan - Semanal'!$I$53+'Plan - Semanal'!$I$54+'Plan - Semanal'!$I$55+'Plan - Semanal'!$I$56 -> 0 | AI13: =AF13-AH13 -> 5460 | AJ13: =AI13/$M13 -> 27.3 | AK13: =+'Plan - Semanal'!$M$53+'Plan - Semanal'!$M$54+'Plan - Semanal'!$M$55+'Plan - Semanal'!$M$56 -> 0 | AL13: =AI13-AK13 -> 5460 | AM13: =AL13/$M13 -> 27.3 | AN13: =+'Plan - Semanal'!$N$53+'Plan - Semanal'!$N$54+'Plan - Semanal'!$N$55+'Plan - Semanal'!$N$56 -> 0 | AO13: =AL13-AN13 -> 5460 | AP13: =AO13/$M13 -> 27.3 | AQ13: =+'Plan - Semanal'!$O$53+'Plan - Semanal'!$O$54+'Plan - Semanal'!$O$55+'Plan - Semanal'!$O$56 -> 0 | AR13: =AO13-AQ13 -> 5460 | AS13: =AR13/M13 -> 27.3
A14: Papel Boquilla - MILENIO VID ICE | B14: Papel Boquilla - MILENIO VID ICE | C14: 1 | D14: BOBINA | E14: 40 | F14: CAJA PT | H14: 42 | I14: BOBINA | K14: =(H14*E14)/C14 -> 1680 | M14: 125 | N14: =K14/M14 -> 13.44 | P14: =+'Plan - Semanal'!$C$57+'Plan - Semanal'!$C$58+'Plan - Semanal'!$C$59+'Plan - Semanal'!$C$60 -> 0 | Q14: =K14-P14 -> 1680 | R14: =Q14/$M14 -> 13.44 | S14: =+'Plan - Semanal'!$D$57+'Plan - Semanal'!$D$58+'Plan - Semanal'!$D$59+'Plan - Semanal'!$D$60 -> 0 | T14: =Q14-S14 -> 1680 | U14: =T14/$M14 -> 13.44 | V14: =+'Plan - Semanal'!$D$57+'Plan - Semanal'!$D$58+'Plan - Semanal'!$D$59+'Plan - Semanal'!$D$60 -> 0 | W14: =T14-V14 -> 1680 | X14: =W14/$M14 -> 13.44 | Y14: =+'Plan - Semanal'!$F$57+'Plan - Semanal'!$F$58+'Plan - Semanal'!$F$59+'Plan - Semanal'!$F$60 -> 0 | Z14: =W14-Y14 -> 1680 | AA14: =Z14/$M14 -> 13.44 | AB14: =+'Plan - Semanal'!$G$57+'Plan - Semanal'!$G$58+'Plan - Semanal'!$G$59+'Plan - Semanal'!$G$60 -> 0 | AC14: =Z14-AB14 -> 1680 | AD14: =AC14/$M14 -> 13.44 | AE14: =+'Plan - Semanal'!$H$57+'Plan - Semanal'!$H$58+'Plan - Semanal'!$H$59+'Plan - Semanal'!$H$60 -> 0 | AF14: =AC14-AE14 -> 1680 | AG14: =AF14/$M14 -> 13.44 | AH14: =+'Plan - Semanal'!$I$57+'Plan - Semanal'!$I$58+'Plan - Semanal'!$I$59+'Plan - Semanal'!$I$60 -> 0 | AI14: =AF14-AH14 -> 1680 | AJ14: =AI14/$M14 -> 13.44 | AK14: =+'Plan - Semanal'!$M$57+'Plan - Semanal'!$M$58+'Plan - Semanal'!$M$59+'Plan - Semanal'!$M$60 -> 0 | AL14: =AI14-AK14 -> 1680 | AM14: =AL14/$M14 -> 13.44 | AN14: =+'Plan - Semanal'!$N$57+'Plan - Semanal'!$N$58+'Plan - Semanal'!$N$59+'Plan - Semanal'!$N$60 -> 0 | AO14: =AL14-AN14 -> 1680 | AP14: =AO14/$M14 -> 13.44 | AQ14: =+'Plan - Semanal'!$O$57+'Plan - Semanal'!$O$58+'Plan - Semanal'!$O$59+'Plan - Semanal'!$O$60 -> 0 | AR14: =AO14-AQ14 -> 1680 | AS14: =AR14/M14 -> 13.44
A15: Papel Boquilla - MILENIO PINK WAVE MINTZ | B15: Papel Boquilla - MILENIO PINK WAVE MINTZ | C15: 1 | D15: BOBINA | E15: 40 | F15: CAJA PT | H15: 61 | I15: BOBINA | K15: =(H15*E15)/C15 -> 2440 | M15: 40 | N15: =K15/M15 -> 61 | P15: =+'Plan - Semanal'!$C$61+'Plan - Semanal'!$C$62+'Plan - Semanal'!$C$63+'Plan - Semanal'!$C$64 -> 0 | Q15: =K15-P15 -> 2440 | R15: =Q15/$M15 -> 61 | S15: =+'Plan - Semanal'!$D$61+'Plan - Semanal'!$D$62+'Plan - Semanal'!$D$63+'Plan - Semanal'!$D$64 -> 0 | T15: =Q15-S15 -> 2440 | U15: =T15/$M15 -> 61 | V15: =+'Plan - Semanal'!$E$61+'Plan - Semanal'!$E$62+'Plan - Semanal'!$E$63+'Plan - Semanal'!$E$64 -> 0 | W15: =T15-V15 -> 2440 | X15: =W15/$M15 -> 61 | Y15: =+'Plan - Semanal'!$F$61+'Plan - Semanal'!$F$62+'Plan - Semanal'!$F$63+'Plan - Semanal'!$F$64 -> 200 | Z15: =W15-Y15 -> 2240 | AA15: =Z15/$M15 -> 56 | AB15: =+'Plan - Semanal'!$G$61+'Plan - Semanal'!$G$62+'Plan - Semanal'!$G$63+'Plan - Semanal'!$G$64 -> 0 | AC15: =Z15-AB15 -> 2240 | AD15: =AC15/$M15 -> 56 | AE15: =+'Plan - Semanal'!$H$61+'Plan - Semanal'!$H$62+'Plan - Semanal'!$H$63+'Plan - Semanal'!$H$64 -> 0 | AF15: =AC15-AE15 -> 2240 | AG15: =AF15/$M15 -> 56 | AH15: =+'Plan - Semanal'!$I$61+'Plan - Semanal'!$I$62+'Plan - Semanal'!$I$63+'Plan - Semanal'!$I$64 -> 0 | AI15: =AF15-AH15 -> 2240 | AJ15: =AI15/$M15 -> 56 | AK15: =+'Plan - Semanal'!$M$61+'Plan - Semanal'!$M$62+'Plan - Semanal'!$M$63+'Plan - Semanal'!$M$64 -> 0 | AL15: =AI15-AK15 -> 2240 | AM15: =AL15/$M15 -> 56 | AN15: =+'Plan - Semanal'!$N$61+'Plan - Semanal'!$N$62+'Plan - Semanal'!$N$63+'Plan - Semanal'!$N$64 -> 0 | AO15: =AL15-AN15 -> 2240 | AP15: =AO15/$M15 -> 56 | AQ15: =+'Plan - Semanal'!$O$61+'Plan - Semanal'!$O$62+'Plan - Semanal'!$O$63+'Plan - Semanal'!$O$64 -> 0 | AR15: =AO15-AQ15 -> 2240 | AS15: =AR15/M15 -> 56
A16: Papel Boquilla - MILL EXPLOSION | B16: Papel Boquilla - MILL EXPLOSION | C16: 1 | D16: BOBINA | E16: 40 | F16: CAJA PT | H16: 154 | I16: BOBINA | K16: =(H16*E16)/C16 -> 6160 | M16: 75 | N16: =K16/M16 -> 82.133333 | P16: =+'Plan - Semanal'!$C$65+'Plan - Semanal'!$C$66+'Plan - Semanal'!$C$67+'Plan - Semanal'!$C$68 -> 0 | Q16: =K16-P16 -> 6160 | R16: =Q16/$M16 -> 82.133333 | S16: =+'Plan - Semanal'!$D$65+'Plan - Semanal'!$D$66+'Plan - Semanal'!$D$67+'Plan - Semanal'!$D$68 -> 0 | T16: =Q16-S16 -> 6160 | U16: =T16/$M16 -> 82.133333 | V16: =+'Plan - Semanal'!$E$65+'Plan - Semanal'!$E$66+'Plan - Semanal'!$E$67+'Plan - Semanal'!$E$68 -> 0 | W16: =T16-V16 -> 6160 | X16: =W16/$M16 -> 82.133333 | Y16: =+'Plan - Semanal'!$F$65+'Plan - Semanal'!$F$66+'Plan - Semanal'!$F$67+'Plan - Semanal'!$F$68 -> 0 | Z16: =W16-Y16 -> 6160 | AA16: =Z16/$M16 -> 82.133333 | AB16: =+'Plan - Semanal'!$G$65+'Plan - Semanal'!$G$66+'Plan - Semanal'!$G$67+'Plan - Semanal'!$G$68 -> 700 | AC16: =Z16-AB16 -> 5460 | AD16: =AC16/$M16 -> 72.8 | AE16: =+'Plan - Semanal'!$H$65+'Plan - Semanal'!$H$66+'Plan - Semanal'!$H$67+'Plan - Semanal'!$H$68 -> 0 | AF16: =AC16-AE16 -> 5460 | AG16: =AF16/$M16 -> 72.8 | AH16: =+'Plan - Semanal'!$I$65+'Plan - Semanal'!$I$66+'Plan - Semanal'!$I$67+'Plan - Semanal'!$I$68 -> 0 | AI16: =AF16-AH16 -> 5460 | AJ16: =AI16/$M16 -> 72.8 | AK16: =+'Plan - Semanal'!$M$65+'Plan - Semanal'!$M$66+'Plan - Semanal'!$M$67+'Plan - Semanal'!$M$68 -> 0 | AL16: =AI16-AK16 -> 5460 | AM16: =AL16/$M16 -> 72.8 | AN16: =+'Plan - Semanal'!$N$65+'Plan - Semanal'!$N$66+'Plan - Semanal'!$N$67+'Plan - Semanal'!$N$68 -> 0 | AO16: =AL16-AN16 -> 5460 | AP16: =AO16/$M16 -> 72.8 | AQ16: =+'Plan - Semanal'!$O$65+'Plan - Semanal'!$O$66+'Plan - Semanal'!$O$67+'Plan - Semanal'!$O$68 -> 0 | AR16: =AO16-AQ16 -> 5460 | AS16: =AR16/M16 -> 72.8
A17: Papel de Fumar | B17: Papel de Fumar para todos los productos | C17: 1 | D17: BOBINA | E17: 19 | F17: CAJA PT | H17: 682 | I17: BOBINA | K17: =(H17*E17)/C17 -> 12958 | M17: 2000 | N17: =K17/M17 -> 6.479 | P17: ='Plan - Semanal'!$C$79 -> 1900 | Q17: =K17-P17 -> 11058 | R17: =Q17/$M17 -> 5.529 | S17: =+'Plan - Semanal'!$D$79 -> 1900 | T17: =Q17-S17 -> 9158 | U17: =T17/$M17 -> 4.579 | V17: =+'Plan - Semanal'!$E$79 -> 1900 | W17: =T17-V17 -> 7258 | X17: =W17/$M17 -> 3.629 | Y17: =+'Plan - Semanal'!$F$79 -> 1900 | Z17: =W17-Y17 -> 5358 | AA17: =Z17/$M17 -> 2.679 | AB17: =+'Plan - Semanal'!$G$79 -> 1900 | AC17: =Z17-AB17 -> 3458 | AD17: =AC17/$M17 -> 1.729 | AE17: =+'Plan - Semanal'!$H$79 -> 700 | AF17: =AC17-AE17 -> 2758 | AG17: =AF17/$M17 -> 1.379 | AH17: =+'Plan - Semanal'!$I$79 -> 0 | AI17: =AF17-AH17 -> 2758 | AJ17: =AI17/$M17 -> 1.379 | AK17: =+'Plan - Semanal'!$M$79 -> 0 | AL17: =AI17-AK17 -> 2758 | AM17: =AL17/$M17 -> 1.379 | AN17: =+'Plan - Semanal'!$N$79 -> 0 | AO17: =AL17-AN17 -> 2758 | AP17: =AO17/$M17 -> 1.379 | AQ17: =+'Plan - Semanal'!$O$79 -> 0 | AR17: =AO17-AQ17 -> 2758 | AS17: =AR17/M17 -> 1.379
A18: Marquilla - MELBOURNE RED | B18: Marquilla SOFT - MELBOURNE RED | C18: 300000 | D18: MARQUILLA | E18: 1200 | F18: CAJA PT | H18: 1012500 | I18: MARQUILLA | K18: =(H18*E18)/C18 -> 4050 | M18: 250 | N18: =K18/M18 -> 16.2 | P18: ='Plan - Semanal'!$C$9+'Plan - Semanal'!$C$10+'Plan - Semanal'!$C$11+'Plan - Semanal'!$C$12 -> 0 | Q18: =K18-P18 -> 4050 | R18: =Q18/$M18 -> 16.2 | S18: ='Plan - Semanal'!$D$9+'Plan - Semanal'!$D$10+'Plan - Semanal'!$D$11+'Plan - Semanal'!$D$12 -> 0 | T18: =Q18-S18 -> 4050 | U18: =T18/$M18 -> 16.2 | V18: ='Plan - Semanal'!$E$9+'Plan - Semanal'!$E$10+'Plan - Semanal'!$E$11+'Plan - Semanal'!$E$12 -> 0 | W18: =T18-V18 -> 4050 | X18: =W18/$M18 -> 16.2 | Y18: ='Plan - Semanal'!$F$9+'Plan - Semanal'!$F$10+'Plan - Semanal'!$F$11+'Plan - Semanal'!$F$12 -> 0 | Z18: =W18-Y18 -> 4050 | AA18: =Z18/$M18 -> 16.2 | AB18: ='Plan - Semanal'!$G$9+'Plan - Semanal'!$G$10+'Plan - Semanal'!$G$11+'Plan - Semanal'!$G$12 -> 0 | AC18: =Z18-AB18 -> 4050 | AD18: =AC18/$M18 -> 16.2 | AE18: ='Plan - Semanal'!$H$9+'Plan - Semanal'!$H$10+'Plan - Semanal'!$H$11+'Plan - Semanal'!$H$12 -> 0 | AF18: =AC18-AE18 -> 4050 | AG18: =AF18/$M18 -> 16.2 | AH18: ='Plan - Semanal'!$I$9+'Plan - Semanal'!$I$10+'Plan - Semanal'!$I$11+'Plan - Semanal'!$I$12 -> 0 | AI18: =AF18-AH18 -> 4050 | AJ18: =AI18/$M18 -> 16.2 | AK18: ='Plan - Semanal'!$M$9+'Plan - Semanal'!$M$10+'Plan - Semanal'!$M$11+'Plan - Semanal'!$M$12 -> 0 | AL18: =AI18-AK18 -> 4050 | AM18: =AL18/$M18 -> 16.2 | AN18: ='Plan - Semanal'!$N$9+'Plan - Semanal'!$N$10+'Plan - Semanal'!$N$11+'Plan - Semanal'!$N$12 -> 0 | AO18: =AL18-AN18 -> 4050 | AP18: =AO18/$M18 -> 16.2 | AQ18: ='Plan - Semanal'!$O$9+'Plan - Semanal'!$O$10+'Plan - Semanal'!$O$11+'Plan - Semanal'!$O$12 -> 0 | AR18: =AO18-AQ18 -> 4050 | AS18: =AR18/M18 -> 16.2
A19: Marquilla - MELBOURNE GOLD | B19: Marquilla SOFT - MELBOURNE GOLD | C19: 300000 | D19: MARQUILLA | E19: 1200 | F19: CAJA PT | H19: 600000 | I19: MARQUILLA | K19: =(H19*E19)/C19 -> 2400 | M19: 35 | N19: =K19/M19 -> 68.571429 | P19: ='Plan - Semanal'!$C$13+'Plan - Semanal'!$C$14+'Plan - Semanal'!$C$15+'Plan - Semanal'!$C$16 -> 0 | Q19: =K19-P19 -> 2400 | R19: =Q19/$M19 -> 68.571429 | S19: ='Plan - Semanal'!$D$13+'Plan - Semanal'!$D$14+'Plan - Semanal'!$D$15+'Plan - Semanal'!$D$16 -> 0 | T19: =Q19-S19 -> 2400 | U19: =T19/$M19 -> 68.571429 | V19: ='Plan - Semanal'!$E$13+'Plan - Semanal'!$E$14+'Plan - Semanal'!$E$15+'Plan - Semanal'!$E$16 -> 0 | W19: =T19-V19 -> 2400 | X19: =W19/$M19 -> 68.571429 | Y19: ='Plan - Semanal'!$F$13+'Plan - Semanal'!$F$14+'Plan - Semanal'!$F$15+'Plan - Semanal'!$F$16 -> 0 | Z19: =W19-Y19 -> 2400 | AA19: =Z19/$M19 -> 68.571429 | AB19: ='Plan - Semanal'!$G$13+'Plan - Semanal'!$G$14+'Plan - Semanal'!$G$15+'Plan - Semanal'!$G$16 -> 0 | AC19: =Z19-AB19 -> 2400 | AD19: =AC19/$M19 -> 68.571429 | AE19: =+'Plan - Semanal'!$H$13+'Plan - Semanal'!$H$14+'Plan - Semanal'!$H$15+'Plan - Semanal'!$H$16 -> 0 | AF19: =AC19-AE19 -> 2400 | AG19: =AF19/$M19 -> 68.571429 | AH19: =+'Plan - Semanal'!$I$13+'Plan - Semanal'!$I$14+'Plan - Semanal'!$I$15+'Plan - Semanal'!$I$16 -> 0 | AI19: =AF19-AH19 -> 2400 | AJ19: =AI19/$M19 -> 68.571429 | AK19: =+'Plan - Semanal'!$M$13+'Plan - Semanal'!$M$14+'Plan - Semanal'!$M$15+'Plan - Semanal'!$M$16 -> 0 | AL19: =AI19-AK19 -> 2400 | AM19: =AL19/$M19 -> 68.571429 | AN19: =+'Plan - Semanal'!$N$13+'Plan - Semanal'!$N$14+'Plan - Semanal'!$N$15+'Plan - Semanal'!$N$16 -> 0 | AO19: =AL19-AN19 -> 2400 | AP19: =AO19/$M19 -> 68.571429 | AQ19: =+'Plan - Semanal'!$O$13+'Plan - Semanal'!$O$14+'Plan - Semanal'!$O$15+'Plan - Semanal'!$O$16 -> 0 | AR19: =AO19-AQ19 -> 2400 | AS19: =AR19/M19 -> 68.571429
A20: Marquilla - MELBOURNE MINT | B20: Marquilla SOFT - MELBOURNE MINT | C20: 300000 | D20: MARQUILLA | E20: 1200 | F20: CAJA PT | H20: 525000 | I20: MARQUILLA | K20: =(H20*E20)/C20 -> 2100 | M20: 20 | N20: =K20/M20 -> 105 | P20: =+'Plan - Semanal'!$C$17+'Plan - Semanal'!$C$18+'Plan - Semanal'!$C$19+'Plan - Semanal'!$C$20 -> 0 | Q20: =K20-P20 -> 2100 | R20: =Q20/$M20 -> 105 | S20: =+'Plan - Semanal'!$D$17+'Plan - Semanal'!$D$18+'Plan - Semanal'!$D$19+'Plan - Semanal'!$D$20 -> 0 | T20: =Q20-S20 -> 2100 | U20: =T20/$M20 -> 105 | V20: =+'Plan - Semanal'!$E$17+'Plan - Semanal'!$E$18+'Plan - Semanal'!$E$19+'Plan - Semanal'!$E$20 -> 0 | W20: =T20-V20 -> 2100 | X20: =W20/$M20 -> 105 | Y20: =+'Plan - Semanal'!$F$17+'Plan - Semanal'!$F$18+'Plan - Semanal'!$F$19+'Plan - Semanal'!$F$20 -> 0 | Z20: =W20-Y20 -> 2100 | AA20: =Z20/$M20 -> 105 | AB20: =+'Plan - Semanal'!$G$17+'Plan - Semanal'!$G$18+'Plan - Semanal'!$G$19+'Plan - Semanal'!$G$20 -> 0 | AC20: =Z20-AB20 -> 2100 | AD20: =AC20/$M20 -> 105 | AE20: =+'Plan - Semanal'!$H$17+'Plan - Semanal'!$H$18+'Plan - Semanal'!$H$19+'Plan - Semanal'!$H$20 -> 0 | AF20: =AC20-AE20 -> 2100 | AG20: =AF20/$M20 -> 105 | AH20: =+'Plan - Semanal'!$I$17+'Plan - Semanal'!$I$18+'Plan - Semanal'!$I$19+'Plan - Semanal'!$I$20 -> 0 | AI20: =AF20-AH20 -> 2100 | AJ20: =AI20/$M20 -> 105 | AK20: =+'Plan - Semanal'!$M$17+'Plan - Semanal'!$M$18+'Plan - Semanal'!$M$19+'Plan - Semanal'!$M$20 -> 0 | AL20: =AI20-AK20 -> 2100 | AM20: =AL20/$M20 -> 105 | AN20: =+'Plan - Semanal'!$N$17+'Plan - Semanal'!$N$18+'Plan - Semanal'!$N$19+'Plan - Semanal'!$N$20 -> 0 | AO20: =AL20-AN20 -> 2100 | AP20: =AO20/$M20 -> 105 | AQ20: =+'Plan - Semanal'!$O$17+'Plan - Semanal'!$O$18+'Plan - Semanal'!$O$19+'Plan - Semanal'!$O$20 -> 0 | AR20: =AO20-AQ20 -> 2100 | AS20: =AR20/M20 -> 105
A21: Marquilla - MILL | B21: Marquilla SOFT - MILL | C21: 300000 | D21: MARQUILLA | E21: 1200 | F21: CAJA PT | H21: 2175000 | I21: MARQUILLA | K21: =(H21*E21)/C21 -> 8700 | M21: 430 | N21: =K21/M21 -> 20.232558 | P21: =+'Plan - Semanal'!$C$21+'Plan - Semanal'!$C$22+'Plan - Semanal'!$C$23+'Plan - Semanal'!$C$24 -> 1200 | Q21: =K21-P21 -> 7500 | R21: =Q21/$M21 -> 17.44186 | S21: =+'Plan - Semanal'!$D$21+'Plan - Semanal'!$D$22+'Plan - Semanal'!$D$23+'Plan - Semanal'!$D$24 -> 1200 | T21: =Q21-S21 -> 6300 | U21: =T21/$M21 -> 14.651163 | V21: =+'Plan - Semanal'!$E$21+'Plan - Semanal'!$E$22+'Plan - Semanal'!$E$23+'Plan - Semanal'!$E$24 -> 1200 | W21: =T21-V21 -> 5100 | X21: =W21/$M21 -> 11.860465 | Y21: =+'Plan - Semanal'!$F$21+'Plan - Semanal'!$F$22+'Plan - Semanal'!$F$23+'Plan - Semanal'!$F$24 -> 0 | Z21: =W21-Y21 -> 5100 | AA21: =Z21/$M21 -> 11.860465 | AB21: =+'Plan - Semanal'!$G$21+'Plan - Semanal'!$G$22+'Plan - Semanal'!$G$23+'Plan - Semanal'!$G$24 -> 0 | AC21: =Z21-AB21 -> 5100 | AD21: =AC21/$M21 -> 11.860465 | AE21: =+'Plan - Semanal'!$H$21+'Plan - Semanal'!$H$22+'Plan - Semanal'!$H$23+'Plan - Semanal'!$H$24 -> 0 | AF21: =AC21-AE21 -> 5100 | AG21: =AF21/$M21 -> 11.860465 | AH21: =+'Plan - Semanal'!$I$21+'Plan - Semanal'!$I$22+'Plan - Semanal'!$I$23+'Plan - Semanal'!$I$24 -> 0 | AI21: =AF21-AH21 -> 5100 | AJ21: =AI21/$M21 -> 11.860465 | AK21: =+'Plan - Semanal'!$M$21+'Plan - Semanal'!$M$22+'Plan - Semanal'!$M$23+'Plan - Semanal'!$M$24 -> 0 | AL21: =AI21-AK21 -> 5100 | AM21: =AL21/$M21 -> 11.860465 | AN21: =+'Plan - Semanal'!$N$21+'Plan - Semanal'!$N$22+'Plan - Semanal'!$N$23+'Plan - Semanal'!$N$24 -> 0 | AO21: =AL21-AN21 -> 5100 | AP21: =AO21/$M21 -> 11.860465 | AQ21: =+'Plan - Semanal'!$O$21+'Plan - Semanal'!$O$22+'Plan - Semanal'!$O$23+'Plan - Semanal'!$O$24 -> 0 | AR21: =AO21-AQ21 -> 5100 | AS21: =AR21/M21 -> 11.860465
A22: Marquilla - MILL MINT | B22: Marquilla SOFT - MILL MINT | C22: 300000 | D22: MARQUILLA | E22: 1200 | F22: CAJA PT | H22: 300000 | I22: MARQUILLA | K22: =(H22*E22)/C22 -> 1200 | M22: 0 | N22: =K22/M22 -> #DIV/0! | P22: =+'Plan - Semanal'!C49+'Plan - Semanal'!C50+'Plan - Semanal'!C51+'Plan - Semanal'!C52 -> 0 | Q22: =K22-P22 -> 1200 | R22: =Q22/$M22 -> #DIV/0! | S22: =+'Plan - Semanal'!D49+'Plan - Semanal'!D50+'Plan - Semanal'!D51+'Plan - Semanal'!D52 -> 0 | T22: =Q22-S22 -> 1200 | U22: =T22/$M22 -> #DIV/0! | V22: =+'Plan - Semanal'!E49+'Plan - Semanal'!E50+'Plan - Semanal'!E51+'Plan - Semanal'!E52 -> 0 | W22: =T22-V22 -> 1200 | X22: =W22/$M22 -> #DIV/0! | Y22: =+'Plan - Semanal'!F49+'Plan - Semanal'!F50+'Plan - Semanal'!F51+'Plan - Semanal'!F52 -> 0 | Z22: =W22-Y22 -> 1200 | AA22: =Z22/$M22 -> #DIV/0! | AB22: =+'Plan - Semanal'!G49+'Plan - Semanal'!G50+'Plan - Semanal'!G51+'Plan - Semanal'!G52 -> 0 | AC22: =Z22-AB22 -> 1200 | AD22: =AC22/$M22 -> #DIV/0! | AE22: =+'Plan - Semanal'!H49+'Plan - Semanal'!H50+'Plan - Semanal'!H51+'Plan - Semanal'!H52 -> 0 | AF22: =AC22-AE22 -> 1200 | AG22: =AF22/$M22 -> #DIV/0! | AH22: =+'Plan - Semanal'!I49+'Plan - Semanal'!I50+'Plan - Semanal'!I51+'Plan - Semanal'!I52 -> 0 | AI22: =AF22-AH22 -> 1200 | AJ22: =AI22/$M22 -> #DIV/0! | AK22: =+'Plan - Semanal'!M49+'Plan - Semanal'!M50+'Plan - Semanal'!M51+'Plan - Semanal'!M52 -> 0 | AL22: =AI22-AK22 -> 1200 | AM22: =AL22/$M22 -> #DIV/0! | AN22: =+'Plan - Semanal'!N49+'Plan - Semanal'!N50+'Plan - Semanal'!N51+'Plan - Semanal'!N52 -> 0 | AO22: =AL22-AN22 -> 1200 | AP22: =AO22/$M22 -> #DIV/0! | AQ22: =+'Plan - Semanal'!O49+'Plan - Semanal'!O50+'Plan - Semanal'!O51+'Plan - Semanal'!O52 -> 0 | AR22: =AO22-AQ22 -> 1200 | AS22: =AR22/M22 -> #DIV/0!
A23: Marquilla - BOLD FULL | B23: Marquilla - BOLD FULL | C23: 300000 | D23: MARQUILLA | E23: =(C23*1)/250 -> 1200 | F23: CAJA PT | H23: 2100000 | I23: MARQUILLA | K23: =(H23*E23)/C23 -> 8400 | M23: 465 | N23: =K23/M23 -> 18.064516 | P23: =+'Plan - Semanal'!$C$29+'Plan - Semanal'!$C$30+'Plan - Semanal'!$C$31+'Plan - Semanal'!$C$32 -> 0 | Q23: =K23-P23 -> 8400 | R23: =Q23/$M23 -> 18.064516 | S23: =+'Plan - Semanal'!$D$29+'Plan - Semanal'!$D$30+'Plan - Semanal'!$D$31+'Plan - Semanal'!$D$32 -> 0 | T23: =Q23-S23 -> 8400 | U23: =T23/$M23 -> 18.064516 | V23: =+'Plan - Semanal'!$E$29+'Plan - Semanal'!$E$30+'Plan - Semanal'!$E$31+'Plan - Semanal'!$E$32 -> 0 | W23: =T23-V23 -> 8400 | X23: =W23/$M23 -> 18.064516 | Y23: =+'Plan - Semanal'!$F$29+'Plan - Semanal'!$F$30+'Plan - Semanal'!$F$31+'Plan - Semanal'!$F$32 -> 1200 | Z23: =W23-Y23 -> 7200 | AA23: =Z23/$M23 -> 15.483871 | AB23: =+'Plan - Semanal'!$G$29+'Plan - Semanal'!$G$30+'Plan - Semanal'!$G$31+'Plan - Semanal'!$G$32 -> 1200 | AC23: =Z23-AB23 -> 6000 | AD23: =AC23/$M23 -> 12.903226 | AE23: =+'Plan - Semanal'!$H$29+'Plan - Semanal'!$H$30+'Plan - Semanal'!$H$31+'Plan - Semanal'!$H$32 -> 0 | AF23: =AC23-AE23 -> 6000 | AG23: =AF23/$M23 -> 12.903226 | AH23: =+'Plan - Semanal'!$I$29+'Plan - Semanal'!$I$30+'Plan - Semanal'!$I$31+'Plan - Semanal'!$I$32 -> 0 | AI23: =AF23-AH23 -> 6000 | AJ23: =AI23/$M23 -> 12.903226 | AK23: =+'Plan - Semanal'!$M$29+'Plan - Semanal'!$M$30+'Plan - Semanal'!$M$31+'Plan - Semanal'!$M$32 -> 0 | AL23: =AI23-AK23 -> 6000 | AM23: =AL23/$M23 -> 12.903226 | AN23: =+'Plan - Semanal'!$N$29+'Plan - Semanal'!$N$30+'Plan - Semanal'!$N$31+'Plan - Semanal'!$N$32 -> 0 | AO23: =AL23-AN23 -> 6000 | AP23: =AO23/$M23 -> 12.903226 | AQ23: =+'Plan - Semanal'!$O$29+'Plan - Semanal'!$O$30+'Plan - Semanal'!$O$31+'Plan - Semanal'!$O$32 -> 0 | AR23: =AO23-AQ23 -> 6000 | AS23: =AR23/M23 -> 12.903226
A24: Marquilla - BOLD MINT | B24: Marquilla - BOLD MINT | C24: 300000 | D24: MARQUILLA | E24: =(C24*1)/250 -> 1200 | F24: CAJA PT | H24: 300000 | I24: MARQUILLA | K24: =(H24*E24)/C24 -> 1200 | M24: 0 | N24: =K24/M24 -> #DIV/0! | P24: =+'Plan - Semanal'!$C$33+'Plan - Semanal'!$C$34+'Plan - Semanal'!$C$35+'Plan - Semanal'!$C$36 -> 0 | Q24: =K24-P24 -> 1200 | R24: =Q24/$M24 -> #DIV/0! | S24: =+'Plan - Semanal'!$D$33+'Plan - Semanal'!$D$34+'Plan - Semanal'!$D$35+'Plan - Semanal'!$D$36 -> 0 | T24: =Q24-S24 -> 1200 | U24: =T24/$M24 -> #DIV/0! | V24: =+'Plan - Semanal'!$E$33+'Plan - Semanal'!$E$34+'Plan - Semanal'!$E$35+'Plan - Semanal'!$E$36 -> 0 | W24: =T24-V24 -> 1200 | X24: =W24/$M24 -> #DIV/0! | Y24: =+'Plan - Semanal'!$F$33+'Plan - Semanal'!$F$34+'Plan - Semanal'!$F$35+'Plan - Semanal'!$F$36 -> 0 | Z24: =W24-Y24 -> 1200 | AA24: =Z24/$M24 -> #DIV/0! | AB24: =+'Plan - Semanal'!$G$33+'Plan - Semanal'!$G$34+'Plan - Semanal'!$G$35+'Plan - Semanal'!$G$36 -> 0 | AC24: =Z24-AB24 -> 1200 | AD24: =AC24/$M24 -> #DIV/0! | AE24: =+'Plan - Semanal'!$H$33+'Plan - Semanal'!$H$34+'Plan - Semanal'!$H$35+'Plan - Semanal'!$H$36 -> 0 | AF24: =AC24-AE24 -> 1200 | AG24: =AF24/$M24 -> #DIV/0! | AH24: =+'Plan - Semanal'!$I$33+'Plan - Semanal'!$I$34+'Plan - Semanal'!$I$35+'Plan - Semanal'!$I$36 -> 0 | AI24: =AF24-AH24 -> 1200 | AJ24: =AI24/$M24 -> #DIV/0! | AK24: =+'Plan - Semanal'!$M$33+'Plan - Semanal'!$M$34+'Plan - Semanal'!$M$35+'Plan - Semanal'!$M$36 -> 0 | AL24: =AI24-AK24 -> 1200 | AM24: =AL24/$M24 -> #DIV/0! | AN24: =+'Plan - Semanal'!$N$33+'Plan - Semanal'!$N$34+'Plan - Semanal'!$N$35+'Plan - Semanal'!$N$36 -> 0 | AO24: =AL24-AN24 -> 1200 | AP24: =AO24/$M24 -> #DIV/0! | AQ24: =+'Plan - Semanal'!$O$33+'Plan - Semanal'!$O$34+'Plan - Semanal'!$O$35+'Plan - Semanal'!$O$36 -> 0 | AR24: =AO24-AQ24 -> 1200 | AS24: =AR24/M24 -> #DIV/0!
A25: Marquilla - MILENIO RED | B25: Marquilla BOX - MILENIO RED | C25: 120000 | D25: MARQUILLA | E25: =(C25*1)/250 -> 480 | F25: CAJA PT | H25: 1924000 | I25: MARQUILLA | K25: =(H25*E25)/C25 -> 7696 | M25: 240 | N25: =K25/M25 -> 32.066667 | P25: ='Plan - Semanal'!$C$41+'Plan - Semanal'!$C$42+'Plan - Semanal'!$C$43+'Plan - Semanal'!$C$44 -> 700 | Q25: =K25-P25 -> 6996 | R25: =Q25/$M25 -> 29.15 | S25: =+'Plan - Semanal'!$D$41+'Plan - Semanal'!$D$42+'Plan - Semanal'!$D$43+'Plan - Semanal'!$D$44 -> 700 | T25: =Q25-S25 -> 6296 | U25: =T25/$M25 -> 26.233333 | V25: =+'Plan - Semanal'!$E$41+'Plan - Semanal'!$E$42+'Plan - Semanal'!$E$43+'Plan - Semanal'!$E$44 -> 700 | W25: =T25-V25 -> 5596 | X25: =W25/$M25 -> 23.316667 | Y25: =+'Plan - Semanal'!$F$41+'Plan - Semanal'!$F$42+'Plan - Semanal'!$F$43+'Plan - Semanal'!$F$44 -> 500 | Z25: =W25-Y25 -> 5096 | AA25: =Z25/$M25 -> 21.233333 | AB25: =+'Plan - Semanal'!$G$41+'Plan - Semanal'!$G$42+'Plan - Semanal'!$G$43+'Plan - Semanal'!$G$44 -> 0 | AC25: =Z25-AB25 -> 5096 | AD25: =AC25/$M25 -> 21.233333 | AE25: =+'Plan - Semanal'!$H$41+'Plan - Semanal'!$H$42+'Plan - Semanal'!$H$43+'Plan - Semanal'!$H$44 -> 0 | AF25: =AC25-AE25 -> 5096 | AG25: =AF25/$M25 -> 21.233333 | AH25: =+'Plan - Semanal'!$I$41+'Plan - Semanal'!$I$42+'Plan - Semanal'!$I$43+'Plan - Semanal'!$I$44 -> 0 | AI25: =AF25-AH25 -> 5096 | AJ25: =AI25/$M25 -> 21.233333 | AK25: =+'Plan - Semanal'!$M$41+'Plan - Semanal'!$M$42+'Plan - Semanal'!$M$43+'Plan - Semanal'!$M$44 -> 0 | AL25: =AI25-AK25 -> 5096 | AM25: =AL25/$M25 -> 21.233333 | AN25: =+'Plan - Semanal'!$N$41+'Plan - Semanal'!$N$42+'Plan - Semanal'!$N$43+'Plan - Semanal'!$N$44 -> 0 | AO25: =AL25-AN25 -> 5096 | AP25: =AO25/$M25 -> 21.233333 | AQ25: =+'Plan - Semanal'!$O$41+'Plan - Semanal'!$O$42+'Plan - Semanal'!$O$43+'Plan - Semanal'!$O$44 -> 0 | AR25: =AO25-AQ25 -> 5096 | AS25: =AR25/M25 -> 21.233333
A26: Marquilla - MILENIO GOLD | B26: Marquilla BOX - MILENIO GOLD | C26: 120000 | D26: MARQUILLA | E26: =(C26*1)/250 -> 480 | F26: CAJA PT | H26: 240000 | I26: MARQUILLA | K26: =(H26*E26)/C26 -> 960 | M26: 25 | N26: =K26/M26 -> 38.4 | P26: =+'Plan - Semanal'!$C$45+'Plan - Semanal'!$C$46+'Plan - Semanal'!$C$47+'Plan - Semanal'!$C$48 -> 0 | Q26: =K26-P26 -> 960 | R26: =Q26/$M26 -> 38.4 | S26: =+'Plan - Semanal'!$D$45+'Plan - Semanal'!$D$46+'Plan - Semanal'!$D$47+'Plan - Semanal'!$D$48 -> 0 | T26: =Q26-S26 -> 960 | U26: =T26/$M26 -> 38.4 | V26: =+'Plan - Semanal'!$E$45+'Plan - Semanal'!$E$46+'Plan - Semanal'!$E$47+'Plan - Semanal'!$E$48 -> 0 | W26: =T26-V26 -> 960 | X26: =W26/$M26 -> 38.4 | Y26: =+'Plan - Semanal'!$F$45+'Plan - Semanal'!$F$46+'Plan - Semanal'!$F$47+'Plan - Semanal'!$F$48 -> 0 | Z26: =W26-Y26 -> 960 | AA26: =Z26/$M26 -> 38.4 | AB26: =+'Plan - Semanal'!$G$45+'Plan - Semanal'!$G$46+'Plan - Semanal'!$G$47+'Plan - Semanal'!$G$48 -> 0 | AC26: =Z26-AB26 -> 960 | AD26: =AC26/$M26 -> 38.4 | AE26: =+'Plan - Semanal'!$H$45+'Plan - Semanal'!$H$46+'Plan - Semanal'!$H$47+'Plan - Semanal'!$H$48 -> 0 | AF26: =AC26-AE26 -> 960 | AG26: =AF26/$M26 -> 38.4 | AH26: =+'Plan - Semanal'!$I$45+'Plan - Semanal'!$I$46+'Plan - Semanal'!$I$47+'Plan - Semanal'!$I$48 -> 0 | AI26: =AF26-AH26 -> 960 | AJ26: =AI26/$M26 -> 38.4 | AK26: =+'Plan - Semanal'!$M$45+'Plan - Semanal'!$M$46+'Plan - Semanal'!$M$47+'Plan - Semanal'!$M$48 -> 0 | AL26: =AI26-AK26 -> 960 | AM26: =AL26/$M26 -> 38.4 | AN26: =+'Plan - Semanal'!$N$45+'Plan - Semanal'!$N$46+'Plan - Semanal'!$N$47+'Plan - Semanal'!$N$48 -> 0 | AO26: =AL26-AN26 -> 960 | AP26: =AO26/$M26 -> 38.4 | AQ26: =+'Plan - Semanal'!$O$45+'Plan - Semanal'!$O$46+'Plan - Semanal'!$O$47+'Plan - Semanal'!$O$48 -> 0 | AR26: =AO26-AQ26 -> 960 | AS26: =AR26/M26 -> 38.4
A27: Marquilla - MILENIO MINT | B27: Marquilla BOX - MILENIO MINT | C27: 120000 | D27: MARQUILLA | E27: =(C27*1)/250 -> 480 | F27: CAJA PT | H27: 720000 | I27: MARQUILLA | K27: =(H27*E27)/C27 -> 2880 | M27: 35 | N27: =K27/M27 -> 82.285714 | P27: =+'Plan - Semanal'!$C$49+'Plan - Semanal'!$C$50+'Plan - Semanal'!$C$51+'Plan - Semanal'!$C$52 -> 0 | Q27: =K27-P27 -> 2880 | R27: =Q27/$M27 -> 82.285714 | S27: =+'Plan - Semanal'!$D$49+'Plan - Semanal'!$D$50+'Plan - Semanal'!$D$51+'Plan - Semanal'!$D$52 -> 0 | T27: =Q27-S27 -> 2880 | U27: =T27/$M27 -> 82.285714 | V27: =+'Plan - Semanal'!$E$49+'Plan - Semanal'!$E$50+'Plan - Semanal'!$E$51+'Plan - Semanal'!$E$52 -> 0 | W27: =T27-V27 -> 2880 | X27: =W27/$M27 -> 82.285714 | Y27: =+'Plan - Semanal'!$F$49+'Plan - Semanal'!$F$50+'Plan - Semanal'!$F$51+'Plan - Semanal'!$F$52 -> 0 | Z27: =W27-Y27 -> 2880 | AA27: =Z27/$M27 -> 82.285714 | AB27: =+'Plan - Semanal'!$G$49+'Plan - Semanal'!$G$50+'Plan - Semanal'!$G$51+'Plan - Semanal'!$G$52 -> 0 | AC27: =Z27-AB27 -> 2880 | AD27: =AC27/$M27 -> 82.285714 | AE27: =+'Plan - Semanal'!$H$49+'Plan - Semanal'!$H$50+'Plan - Semanal'!$H$51+'Plan - Semanal'!$H$52 -> 0 | AF27: =AC27-AE27 -> 2880 | AG27: =AF27/$M27 -> 82.285714 | AH27: =+'Plan - Semanal'!$I$49+'Plan - Semanal'!$I$50+'Plan - Semanal'!$I$51+'Plan - Semanal'!$I$52 -> 0 | AI27: =AF27-AH27 -> 2880 | AJ27: =AI27/$M27 -> 82.285714 | AK27: =+'Plan - Semanal'!$M$49+'Plan - Semanal'!$M$50+'Plan - Semanal'!$M$51+'Plan - Semanal'!$M$52 -> 0 | AL27: =AI27-AK27 -> 2880 | AM27: =AL27/$M27 -> 82.285714 | AN27: =+'Plan - Semanal'!$N$49+'Plan - Semanal'!$N$50+'Plan - Semanal'!$N$51+'Plan - Semanal'!$N$52 -> 0 | AO27: =AL27-AN27 -> 2880 | AP27: =AO27/$M27 -> 82.285714 | AQ27: =+'Plan - Semanal'!$O$49+'Plan - Semanal'!$O$50+'Plan - Semanal'!$O$51+'Plan - Semanal'!$O$52 -> 0 | AR27: =AO27-AQ27 -> 2880 | AS27: =AR27/M27 -> 82.285714
A28: Marquilla - MILENIO ICERGY | B28: Marquilla BOX - MILENIO ICERGY | C28: 144000 | D28: MARQUILLA | E28: =(C28*1)/250 -> 576 | F28: CAJA PT | H28: 144000 | I28: MARQUILLA | K28: =(H28*E28)/C28 -> 576 | M28: 200 | N28: =K28/M28 -> 2.88 | P28: =+'Plan - Semanal'!$C$53+'Plan - Semanal'!$C$54+'Plan - Semanal'!$C$55+'Plan - Semanal'!$C$56 -> 0 | Q28: =K28-P28 -> 576 | R28: =Q28/$M28 -> 2.88 | S28: =+'Plan - Semanal'!$D$53+'Plan - Semanal'!$D$54+'Plan - Semanal'!$D$55+'Plan - Semanal'!$D$56 -> 0 | T28: =Q28-S28 -> 576 | U28: =T28/$M28 -> 2.88 | V28: =+'Plan - Semanal'!$E$53+'Plan - Semanal'!$E$54+'Plan - Semanal'!$E$55+'Plan - Semanal'!$E$56 -> 0 | W28: =T28-V28 -> 576 | X28: =W28/$M28 -> 2.88 | Y28: =+'Plan - Semanal'!$F$53+'Plan - Semanal'!$F$54+'Plan - Semanal'!$F$55+'Plan - Semanal'!$F$56 -> 0 | Z28: =W28-Y28 -> 576 | AA28: =Z28/$M28 -> 2.88 | AB28: =+'Plan - Semanal'!$G$53+'Plan - Semanal'!$G$54+'Plan - Semanal'!$G$55+'Plan - Semanal'!$G$56 -> 0 | AC28: =Z28-AB28 -> 576 | AD28: =AC28/$M28 -> 2.88 | AE28: =+'Plan - Semanal'!$H$53+'Plan - Semanal'!$H$54+'Plan - Semanal'!$H$55+'Plan - Semanal'!$H$56 -> 700 | AF28: =AC28-AE28 -> -124 | AG28: =AF28/$M28 -> -0.62 | AH28: =+'Plan - Semanal'!$I$53+'Plan - Semanal'!$I$54+'Plan - Semanal'!$I$55+'Plan - Semanal'!$I$56 -> 0 | AI28: =AF28-AH28 -> -124 | AJ28: =AI28/$M28 -> -0.62 | AK28: =+'Plan - Semanal'!$M$53+'Plan - Semanal'!$M$54+'Plan - Semanal'!$M$55+'Plan - Semanal'!$M$56 -> 0 | AL28: =AI28-AK28 -> -124 | AM28: =AL28/$M28 -> -0.62 | AN28: =+'Plan - Semanal'!$N$53+'Plan - Semanal'!$N$54+'Plan - Semanal'!$N$55+'Plan - Semanal'!$N$56 -> 0 | AO28: =AL28-AN28 -> -124 | AP28: =AO28/$M28 -> -0.62 | AQ28: =+'Plan - Semanal'!$O$53+'Plan - Semanal'!$O$54+'Plan - Semanal'!$O$55+'Plan - Semanal'!$O$56 -> 0 | AR28: =AO28-AQ28 -> -124 | AS28: =AR28/M28 -> -0.62
A29: Marquilla - MILENIO VID ICE | B29: Marquilla BOX - MILENIO VID ICE | C29: 120000 | D29: MARQUILLA | E29: =(C29*1)/250 -> 480 | F29: CAJA PT | H29: 1128000 | I29: MARQUILLA | K29: =(H29*E29)/C29 -> 4512 | M29: 125 | N29: =K29/M29 -> 36.096 | P29: =+'Plan - Semanal'!$C$57+'Plan - Semanal'!$C$58+'Plan - Semanal'!$C$59+'Plan - Semanal'!$C$60 -> 0 | Q29: =K29-P29 -> 4512 | R29: =Q29/$M29 -> 36.096 | S29: =+'Plan - Semanal'!$D$57+'Plan - Semanal'!$D$58+'Plan - Semanal'!$D$59+'Plan - Semanal'!$D$60 -> 0 | T29: =Q29-S29 -> 4512 | U29: =T29/$M29 -> 36.096 | V29: =+'Plan - Semanal'!$D$57+'Plan - Semanal'!$D$58+'Plan - Semanal'!$D$59+'Plan - Semanal'!$D$60 -> 0 | W29: =T29-V29 -> 4512 | X29: =W29/$M29 -> 36.096 | Y29: =+'Plan - Semanal'!$F$57+'Plan - Semanal'!$F$58+'Plan - Semanal'!$F$59+'Plan - Semanal'!$F$60 -> 0 | Z29: =W29-Y29 -> 4512 | AA29: =Z29/$M29 -> 36.096 | AB29: =+'Plan - Semanal'!$G$57+'Plan - Semanal'!$G$58+'Plan - Semanal'!$G$59+'Plan - Semanal'!$G$60 -> 0 | AC29: =Z29-AB29 -> 4512 | AD29: =AC29/$M29 -> 36.096 | AE29: =+'Plan - Semanal'!$H$57+'Plan - Semanal'!$H$58+'Plan - Semanal'!$H$59+'Plan - Semanal'!$H$60 -> 0 | AF29: =AC29-AE29 -> 4512 | AG29: =AF29/$M29 -> 36.096 | AH29: =+'Plan - Semanal'!$I$57+'Plan - Semanal'!$I$58+'Plan - Semanal'!$I$59+'Plan - Semanal'!$I$60 -> 0 | AI29: =AF29-AH29 -> 4512 | AJ29: =AI29/$M29 -> 36.096 | AK29: =+'Plan - Semanal'!$M$57+'Plan - Semanal'!$M$58+'Plan - Semanal'!$M$59+'Plan - Semanal'!$M$60 -> 0 | AL29: =AI29-AK29 -> 4512 | AM29: =AL29/$M29 -> 36.096 | AN29: =+'Plan - Semanal'!$N$57+'Plan - Semanal'!$N$58+'Plan - Semanal'!$N$59+'Plan - Semanal'!$N$60 -> 0 | AO29: =AL29-AN29 -> 4512 | AP29: =AO29/$M29 -> 36.096 | AQ29: =+'Plan - Semanal'!$O$57+'Plan - Semanal'!$O$58+'Plan - Semanal'!$O$59+'Plan - Semanal'!$O$60 -> 0 | AR29: =AO29-AQ29 -> 4512 | AS29: =AR29/M29 -> 36.096
A30: Marquilla - MILENIO PINK WAVE MINTZ | B30: Marquilla BOX - MILENIO PINK WAVE MINTZ | C30: 144000 | D30: MARQUILLA | E30: =(C30*1)/250 -> 576 | F30: CAJA PT | H30: 912000 | I30: MARQUILLA | K30: =(H30*E30)/C30 -> 3648 | M30: 40 | N30: =K30/M30 -> 91.2 | P30: =+'Plan - Semanal'!$C$61+'Plan - Semanal'!$C$62+'Plan - Semanal'!$C$63+'Plan - Semanal'!$C$64 -> 0 | Q30: =K30-P30 -> 3648 | R30: =Q30/$M30 -> 91.2 | S30: =+'Plan - Semanal'!$D$61+'Plan - Semanal'!$D$62+'Plan - Semanal'!$D$63+'Plan - Semanal'!$D$64 -> 0 | T30: =Q30-S30 -> 3648 | U30: =T30/$M30 -> 91.2 | V30: =+'Plan - Semanal'!$E$61+'Plan - Semanal'!$E$62+'Plan - Semanal'!$E$63+'Plan - Semanal'!$E$64 -> 0 | W30: =T30-V30 -> 3648 | X30: =W30/$M30 -> 91.2 | Y30: =+'Plan - Semanal'!$F$61+'Plan - Semanal'!$F$62+'Plan - Semanal'!$F$63+'Plan - Semanal'!$F$64 -> 200 | Z30: =W30-Y30 -> 3448 | AA30: =Z30/$M30 -> 86.2 | AB30: =+'Plan - Semanal'!$G$61+'Plan - Semanal'!$G$62+'Plan - Semanal'!$G$63+'Plan - Semanal'!$G$64 -> 0 | AC30: =Z30-AB30 -> 3448 | AD30: =AC30/$M30 -> 86.2 | AE30: =+'Plan - Semanal'!$H$61+'Plan - Semanal'!$H$62+'Plan - Semanal'!$H$63+'Plan - Semanal'!$H$64 -> 0 | AF30: =AC30-AE30 -> 3448 | AG30: =AF30/$M30 -> 86.2 | AH30: =+'Plan - Semanal'!$I$61+'Plan - Semanal'!$I$62+'Plan - Semanal'!$I$63+'Plan - Semanal'!$I$64 -> 0 | AI30: =AF30-AH30 -> 3448 | AJ30: =AI30/$M30 -> 86.2 | AK30: =+'Plan - Semanal'!$M$61+'Plan - Semanal'!$M$62+'Plan - Semanal'!$M$63+'Plan - Semanal'!$M$64 -> 0 | AL30: =AI30-AK30 -> 3448 | AM30: =AL30/$M30 -> 86.2 | AN30: =+'Plan - Semanal'!$N$61+'Plan - Semanal'!$N$62+'Plan - Semanal'!$N$63+'Plan - Semanal'!$N$64 -> 0 | AO30: =AL30-AN30 -> 3448 | AP30: =AO30/$M30 -> 86.2 | AQ30: =+'Plan - Semanal'!$O$61+'Plan - Semanal'!$O$62+'Plan - Semanal'!$O$63+'Plan - Semanal'!$O$64 -> 0 | AR30: =AO30-AQ30 -> 3448 | AS30: =AR30/M30 -> 86.2
